{
  "version": 8,
  "blockIdVersion": 11,
  "anchorX": 0,
  "anchorY": 0,
  "anchorZ": 0,
  "blocks": [
    {
      "x": -2,
      "y": 3,
      "z": 0,
      "name": "Build_Lightsource_White",
      "support": 15,
      "rotation": 4
    },
    {
      "x": -2,
      "y": 6,
      "z": 0,
      "name": "Build_Lightsource_White",
      "support": 15,
      "rotation": 4
    },
    {
      "x": -1,
      "y": 1,
      "z": -13,
      "name": "Soil_Clay_Smooth_Black_Stairs",
      "rotation": 34
    },
    {
      "x": -1,
      "y": 2,
      "z": -13,
      "name": "Soil_Clay_Smooth_Black",
      "support": 15
    },
    {
      "x": -1,
      "y": 3,
      "z": -13,
      "name": "Soil_Clay_Smooth_Black",
      "support": 15
    },
    {
      "x": -1,
      "y": 4,
      "z": -13,
      "name": "Soil_Clay_Smooth_Black"
    },
    {
      "x": -1,
      "y": 5,
      "z": -13,
      "name": "Soil_Clay_Smooth_Black"
    },
    {
      "x": -1,
      "y": 6,
      "z": -13,
      "name": "Soil_Clay_Smooth_Black"
    },
    {
      "x": -1,
      "y": 7,
      "z": -13,
      "name": "Soil_Clay_Smooth_Black",
      "support": 15
    },
    {
      "x": -1,
      "y": 8,
      "z": -13,
      "name": "Soil_Clay_Smooth_Black",
      "support": 15
    },
    {
      "x": -1,
      "y": 9,
      "z": -13,
      "name": "Soil_Clay_Smooth_Black_Stairs",
      "rotation": 2
    },
    {
      "x": -1,
      "y": 1,
      "z": -12,
      "name": "Soil_Clay_Smooth_Black"
    },
    {
      "x": -1,
      "y": 2,
      "z": -12,
      "name": "Soil_Clay_Smooth_Black",
      "support": 15
    },
    {
      "x": -1,
      "y": 3,
      "z": -12,
      "name": "Soil_Clay_Smooth_Black",
      "support": 15
    },
    {
      "x": -1,
      "y": 4,
      "z": -12,
      "name": "Soil_Clay_Smooth_Black",
      "support": 15
    },
    {
      "x": -1,
      "y": 5,
      "z": -12,
      "name": "Soil_Clay_Smooth_Black",
      "support": 15
    },
    {
      "x": -1,
      "y": 6,
      "z": -12,
      "name": "Soil_Clay_Smooth_Black",
      "support": 15
    },
    {
      "x": -1,
      "y": 7,
      "z": -12,
      "name": "Soil_Clay_Smooth_Black",
      "support": 15
    },
    {
      "x": -1,
      "y": 8,
      "z": -12,
      "name": "Soil_Clay_Smooth_Black",
      "support": 15
    },
    {
      "x": -1,
      "y": 9,
      "z": -12,
      "name": "Soil_Clay_Smooth_Black"
    },
    {
      "x": -1,
      "y": 1,
      "z": -11,
      "name": "Soil_Clay_Smooth_Black"
    },
    {
      "x": -1,
      "y": 2,
      "z": -11,
      "name": "Soil_Clay_Smooth_Black",
      "support": 15
    },
    {
      "x": -1,
      "y": 3,
      "z": -11,
      "name": "Soil_Clay_Smooth_Black",
      "support": 15
    },
    {
      "x": -1,
      "y": 4,
      "z": -11,
      "name": "Soil_Clay_Smooth_Black"
    },
    {
      "x": -1,
      "y": 5,
      "z": -11,
      "name": "Soil_Clay_Smooth_Black"
    },
    {
      "x": -1,
      "y": 6,
      "z": -11,
      "name": "Soil_Clay_Smooth_Black"
    },
    {
      "x": -1,
      "y": 7,
      "z": -11,
      "name": "Soil_Clay_Smooth_Black",
      "support": 15
    },
    {
      "x": -1,
      "y": 8,
      "z": -11,
      "name": "Soil_Clay_Smooth_Black",
      "support": 15
    },
    {
      "x": -1,
      "y": 9,
      "z": -11,
      "name": "Soil_Clay_Smooth_Black"
    },
    {
      "x": -1,
      "y": 1,
      "z": -10,
      "name": "Soil_Clay_Smooth_Black"
    },
    {
      "x": -1,
      "y": 2,
      "z": -10,
      "name": "Soil_Clay_Smooth_Black",
      "support": 15
    },
    {
      "x": -1,
      "y": 3,
      "z": -10,
      "name": "Soil_Clay_Smooth_Black"
    },
    {
      "x": -1,
      "y": 4,
      "z": -10,
      "name": "Soil_Clay_Smooth_Black"
    },
    {
      "x": -1,
      "y": 5,
      "z": -10,
      "name": "Soil_Clay_Smooth_Black"
    },
    {
      "x": -1,
      "y": 6,
      "z": -10,
      "name": "Soil_Clay_Smooth_Black"
    },
    {
      "x": -1,
      "y": 7,
      "z": -10,
      "name": "Soil_Clay_Smooth_Black"
    },
    {
      "x": -1,
      "y": 8,
      "z": -10,
      "name": "Soil_Clay_Smooth_Black",
      "support": 15
    },
    {
      "x": -1,
      "y": 9,
      "z": -10,
      "name": "Soil_Clay_Smooth_Black"
    },
    {
      "x": -1,
      "y": 1,
      "z": -9,
      "name": "Soil_Clay_Smooth_Black"
    },
    {
      "x": -1,
      "y": 2,
      "z": -9,
      "name": "Soil_Clay_Smooth_Black",
      "support": 15
    },
    {
      "x": -1,
      "y": 3,
      "z": -9,
      "name": "Soil_Clay_Smooth_Black",
      "support": 15
    },
    {
      "x": -1,
      "y": 4,
      "z": -9,
      "name": "Soil_Clay_Smooth_Black"
    },
    {
      "x": -1,
      "y": 5,
      "z": -9,
      "name": "Soil_Clay_Smooth_Black"
    },
    {
      "x": -1,
      "y": 6,
      "z": -9,
      "name": "Soil_Clay_Smooth_Black"
    },
    {
      "x": -1,
      "y": 7,
      "z": -9,
      "name": "Soil_Clay_Smooth_Black",
      "support": 15
    },
    {
      "x": -1,
      "y": 8,
      "z": -9,
      "name": "Soil_Clay_Smooth_Black",
      "support": 15
    },
    {
      "x": -1,
      "y": 9,
      "z": -9,
      "name": "Soil_Clay_Smooth_Black"
    },
    {
      "x": -1,
      "y": 1,
      "z": -8,
      "name": "Soil_Clay_Smooth_Black"
    },
    {
      "x": -1,
      "y": 2,
      "z": -8,
      "name": "Soil_Clay_Smooth_Black",
      "support": 15
    },
    {
      "x": -1,
      "y": 3,
      "z": -8,
      "name": "Soil_Clay_Smooth_Black",
      "support": 15
    },
    {
      "x": -1,
      "y": 4,
      "z": -8,
      "name": "Soil_Clay_Smooth_Black",
      "support": 15
    },
    {
      "x": -1,
      "y": 5,
      "z": -8,
      "name": "Soil_Clay_Smooth_Black",
      "support": 15
    },
    {
      "x": -1,
      "y": 6,
      "z": -8,
      "name": "Soil_Clay_Smooth_Black",
      "support": 15
    },
    {
      "x": -1,
      "y": 7,
      "z": -8,
      "name": "Soil_Clay_Smooth_Black",
      "support": 15
    },
    {
      "x": -1,
      "y": 8,
      "z": -8,
      "name": "Soil_Clay_Smooth_Black",
      "support": 15
    },
    {
      "x": -1,
      "y": 9,
      "z": -8,
      "name": "Soil_Clay_Smooth_Black"
    },
    {
      "x": -1,
      "y": 1,
      "z": -7,
      "name": "Soil_Clay_Smooth_Black"
    },
    {
      "x": -1,
      "y": 2,
      "z": -7,
      "name": "Soil_Clay_Smooth_Black",
      "support": 15
    },
    {
      "x": -1,
      "y": 3,
      "z": -7,
      "name": "Soil_Clay_Smooth_Black",
      "support": 15
    },
    {
      "x": -1,
      "y": 4,
      "z": -7,
      "name": "Soil_Clay_Smooth_Black",
      "support": 15
    },
    {
      "x": -1,
      "y": 5,
      "z": -7,
      "name": "Soil_Clay_Smooth_Black",
      "support": 15
    },
    {
      "x": -1,
      "y": 6,
      "z": -7,
      "name": "Soil_Clay_Smooth_Black",
      "support": 15
    },
    {
      "x": -1,
      "y": 7,
      "z": -7,
      "name": "Soil_Clay_Smooth_Black",
      "support": 15
    },
    {
      "x": -1,
      "y": 8,
      "z": -7,
      "name": "Soil_Clay_Smooth_Black",
      "support": 15
    },
    {
      "x": -1,
      "y": 9,
      "z": -7,
      "name": "Soil_Clay_Smooth_Black"
    },
    {
      "x": -1,
      "y": 1,
      "z": -6,
      "name": "Soil_Clay_Smooth_Black"
    },
    {
      "x": -1,
      "y": 2,
      "z": -6,
      "name": "Soil_Clay_Smooth_Black",
      "support": 15
    },
    {
      "x": -1,
      "y": 3,
      "z": -6,
      "name": "Soil_Clay_Smooth_Black",
      "support": 15
    },
    {
      "x": -1,
      "y": 4,
      "z": -6,
      "name": "Soil_Clay_Smooth_Black",
      "support": 15
    },
    {
      "x": -1,
      "y": 5,
      "z": -6,
      "name": "Soil_Clay_Smooth_Black",
      "support": 15
    },
    {
      "x": -1,
      "y": 6,
      "z": -6,
      "name": "Soil_Clay_Smooth_Black",
      "support": 15
    },
    {
      "x": -1,
      "y": 7,
      "z": -6,
      "name": "Soil_Clay_Smooth_Black",
      "support": 15
    },
    {
      "x": -1,
      "y": 8,
      "z": -6,
      "name": "Soil_Clay_Smooth_Black",
      "support": 15
    },
    {
      "x": -1,
      "y": 9,
      "z": -6,
      "name": "Soil_Clay_Smooth_Black"
    },
    {
      "x": -1,
      "y": 1,
      "z": -5,
      "name": "Soil_Clay_Smooth_Black"
    },
    {
      "x": -1,
      "y": 2,
      "z": -5,
      "name": "Soil_Clay_Smooth_Black",
      "support": 15
    },
    {
      "x": -1,
      "y": 3,
      "z": -5,
      "name": "Soil_Clay_Smooth_Black",
      "support": 15
    },
    {
      "x": -1,
      "y": 4,
      "z": -5,
      "name": "Soil_Clay_Smooth_Black"
    },
    {
      "x": -1,
      "y": 5,
      "z": -5,
      "name": "Soil_Clay_Smooth_Black"
    },
    {
      "x": -1,
      "y": 6,
      "z": -5,
      "name": "Soil_Clay_Smooth_Black"
    },
    {
      "x": -1,
      "y": 7,
      "z": -5,
      "name": "Soil_Clay_Smooth_Black",
      "support": 15
    },
    {
      "x": -1,
      "y": 8,
      "z": -5,
      "name": "Soil_Clay_Smooth_Black",
      "support": 15
    },
    {
      "x": -1,
      "y": 9,
      "z": -5,
      "name": "Soil_Clay_Smooth_Black"
    },
    {
      "x": -1,
      "y": 1,
      "z": -4,
      "name": "Soil_Clay_Smooth_Black"
    },
    {
      "x": -1,
      "y": 2,
      "z": -4,
      "name": "Soil_Clay_Smooth_Black",
      "support": 15
    },
    {
      "x": -1,
      "y": 3,
      "z": -4,
      "name": "Soil_Clay_Smooth_Black",
      "support": 15
    },
    {
      "x": -1,
      "y": 4,
      "z": -4,
      "name": "Soil_Clay_Smooth_Black"
    },
    {
      "x": -1,
      "y": 5,
      "z": -4,
      "name": "Soil_Clay_Smooth_Black"
    },
    {
      "x": -1,
      "y": 6,
      "z": -4,
      "name": "Soil_Clay_Smooth_Black"
    },
    {
      "x": -1,
      "y": 7,
      "z": -4,
      "name": "Soil_Clay_Smooth_Black",
      "support": 15
    },
    {
      "x": -1,
      "y": 8,
      "z": -4,
      "name": "Soil_Clay_Smooth_Black",
      "support": 15
    },
    {
      "x": -1,
      "y": 9,
      "z": -4,
      "name": "Soil_Clay_Smooth_Black"
    },
    {
      "x": -1,
      "y": 1,
      "z": -3,
      "name": "Soil_Clay_Smooth_Black"
    },
    {
      "x": -1,
      "y": 2,
      "z": -3,
      "name": "Soil_Clay_Smooth_Black",
      "support": 15
    },
    {
      "x": -1,
      "y": 3,
      "z": -3,
      "name": "Soil_Clay_Smooth_Black",
      "support": 15
    },
    {
      "x": -1,
      "y": 4,
      "z": -3,
      "name": "Soil_Clay_Smooth_Black",
      "support": 15
    },
    {
      "x": -1,
      "y": 5,
      "z": -3,
      "name": "Soil_Clay_Smooth_Black",
      "support": 15
    },
    {
      "x": -1,
      "y": 6,
      "z": -3,
      "name": "Soil_Clay_Smooth_Black",
      "support": 15
    },
    {
      "x": -1,
      "y": 7,
      "z": -3,
      "name": "Soil_Clay_Smooth_Black",
      "support": 15
    },
    {
      "x": -1,
      "y": 8,
      "z": -3,
      "name": "Soil_Clay_Smooth_Black",
      "support": 15
    },
    {
      "x": -1,
      "y": 9,
      "z": -3,
      "name": "Soil_Clay_Smooth_Black"
    },
    {
      "x": -1,
      "y": 1,
      "z": -2,
      "name": "Soil_Clay_Smooth_Black"
    },
    {
      "x": -1,
      "y": 2,
      "z": -2,
      "name": "Soil_Clay_Smooth_Black",
      "support": 15
    },
    {
      "x": -1,
      "y": 3,
      "z": -2,
      "name": "Soil_Clay_Smooth_Black",
      "support": 15
    },
    {
      "x": -1,
      "y": 4,
      "z": -2,
      "name": "Soil_Clay_Smooth_Black",
      "support": 15
    },
    {
      "x": -1,
      "y": 5,
      "z": -2,
      "name": "Soil_Clay_Smooth_Black",
      "support": 15
    },
    {
      "x": -1,
      "y": 6,
      "z": -2,
      "name": "Soil_Clay_Smooth_Black",
      "support": 15
    },
    {
      "x": -1,
      "y": 7,
      "z": -2,
      "name": "Soil_Clay_Smooth_Black",
      "support": 15
    },
    {
      "x": -1,
      "y": 8,
      "z": -2,
      "name": "Soil_Clay_Smooth_Black",
      "support": 15
    },
    {
      "x": -1,
      "y": 9,
      "z": -2,
      "name": "Soil_Clay_Smooth_Black"
    },
    {
      "x": -1,
      "y": 1,
      "z": -1,
      "name": "Soil_Clay_Smooth_Black"
    },
    {
      "x": -1,
      "y": 2,
      "z": -1,
      "name": "Soil_Clay_Smooth_Black"
    },
    {
      "x": -1,
      "y": 3,
      "z": -1,
      "name": "Soil_Clay_Smooth_Black"
    },
    {
      "x": -1,
      "y": 4,
      "z": -1,
      "name": "Soil_Clay_Smooth_Black"
    },
    {
      "x": -1,
      "y": 5,
      "z": -1,
      "name": "Soil_Clay_Smooth_Black"
    },
    {
      "x": -1,
      "y": 6,
      "z": -1,
      "name": "Soil_Clay_Smooth_Black"
    },
    {
      "x": -1,
      "y": 7,
      "z": -1,
      "name": "Soil_Clay_Smooth_Black"
    },
    {
      "x": -1,
      "y": 8,
      "z": -1,
      "name": "Soil_Clay_Smooth_Black"
    },
    {
      "x": -1,
      "y": 9,
      "z": -1,
      "name": "Soil_Clay_Smooth_Black"
    },
    {
      "x": -1,
      "y": 1,
      "z": 0,
      "name": "Soil_Clay_Smooth_Black"
    },
    {
      "x": -1,
      "y": 2,
      "z": 0,
      "name": "Soil_Clay_Smooth_Black"
    },
    {
      "x": -1,
      "y": 3,
      "z": 0,
      "name": "Soil_Clay_Smooth_Black",
      "support": 15
    },
    {
      "x": -1,
      "y": 4,
      "z": 0,
      "name": "Soil_Clay_Smooth_Black"
    },
    {
      "x": -1,
      "y": 5,
      "z": 0,
      "name": "Soil_Clay_Smooth_Black"
    },
    {
      "x": -1,
      "y": 6,
      "z": 0,
      "name": "Soil_Clay_Smooth_Black"
    },
    {
      "x": -1,
      "y": 7,
      "z": 0,
      "name": "Soil_Clay_Smooth_Black",
      "support": 15
    },
    {
      "x": -1,
      "y": 8,
      "z": 0,
      "name": "Soil_Clay_Smooth_Black"
    },
    {
      "x": -1,
      "y": 9,
      "z": 0,
      "name": "Soil_Clay_Smooth_Black"
    },
    {
      "x": -1,
      "y": 1,
      "z": 1,
      "name": "Soil_Clay_Smooth_Black"
    },
    {
      "x": -1,
      "y": 2,
      "z": 1,
      "name": "Soil_Clay_Smooth_Black"
    },
    {
      "x": -1,
      "y": 3,
      "z": 1,
      "name": "Soil_Clay_Smooth_Black"
    },
    {
      "x": -1,
      "y": 4,
      "z": 1,
      "name": "Soil_Clay_Smooth_Black"
    },
    {
      "x": -1,
      "y": 5,
      "z": 1,
      "name": "Soil_Clay_Smooth_Black"
    },
    {
      "x": -1,
      "y": 6,
      "z": 1,
      "name": "Soil_Clay_Smooth_Black"
    },
    {
      "x": -1,
      "y": 7,
      "z": 1,
      "name": "Soil_Clay_Smooth_Black"
    },
    {
      "x": -1,
      "y": 8,
      "z": 1,
      "name": "Soil_Clay_Smooth_Black"
    },
    {
      "x": -1,
      "y": 9,
      "z": 1,
      "name": "Soil_Clay_Smooth_Black"
    },
    {
      "x": -1,
      "y": 1,
      "z": 2,
      "name": "Soil_Clay_Smooth_Black"
    },
    {
      "x": -1,
      "y": 2,
      "z": 2,
      "name": "Soil_Clay_Smooth_Black",
      "support": 15
    },
    {
      "x": -1,
      "y": 3,
      "z": 2,
      "name": "Soil_Clay_Smooth_Black",
      "support": 15
    },
    {
      "x": -1,
      "y": 4,
      "z": 2,
      "name": "Soil_Clay_Smooth_Black",
      "support": 15
    },
    {
      "x": -1,
      "y": 5,
      "z": 2,
      "name": "Soil_Clay_Smooth_Black",
      "support": 15
    },
    {
      "x": -1,
      "y": 6,
      "z": 2,
      "name": "Soil_Clay_Smooth_Black",
      "support": 15
    },
    {
      "x": -1,
      "y": 7,
      "z": 2,
      "name": "Soil_Clay_Smooth_Black",
      "support": 15
    },
    {
      "x": -1,
      "y": 8,
      "z": 2,
      "name": "Soil_Clay_Smooth_Black",
      "support": 15
    },
    {
      "x": -1,
      "y": 9,
      "z": 2,
      "name": "Soil_Clay_Smooth_Black"
    },
    {
      "x": -1,
      "y": 1,
      "z": 3,
      "name": "Soil_Clay_Smooth_Black"
    },
    {
      "x": -1,
      "y": 2,
      "z": 3,
      "name": "Soil_Clay_Smooth_Black",
      "support": 15
    },
    {
      "x": -1,
      "y": 3,
      "z": 3,
      "name": "Soil_Clay_Smooth_Black",
      "support": 15
    },
    {
      "x": -1,
      "y": 4,
      "z": 3,
      "name": "Soil_Clay_Smooth_Black",
      "support": 15
    },
    {
      "x": -1,
      "y": 5,
      "z": 3,
      "name": "Soil_Clay_Smooth_Black",
      "support": 15
    },
    {
      "x": -1,
      "y": 6,
      "z": 3,
      "name": "Soil_Clay_Smooth_Black",
      "support": 15
    },
    {
      "x": -1,
      "y": 7,
      "z": 3,
      "name": "Soil_Clay_Smooth_Black",
      "support": 15
    },
    {
      "x": -1,
      "y": 8,
      "z": 3,
      "name": "Soil_Clay_Smooth_Black",
      "support": 15
    },
    {
      "x": -1,
      "y": 9,
      "z": 3,
      "name": "Soil_Clay_Smooth_Black"
    },
    {
      "x": -1,
      "y": 1,
      "z": 4,
      "name": "Soil_Clay_Smooth_Black"
    },
    {
      "x": -1,
      "y": 2,
      "z": 4,
      "name": "Soil_Clay_Smooth_Black",
      "support": 15
    },
    {
      "x": -1,
      "y": 3,
      "z": 4,
      "name": "Soil_Clay_Smooth_Black",
      "support": 15
    },
    {
      "x": -1,
      "y": 4,
      "z": 4,
      "name": "Soil_Clay_Smooth_Black"
    },
    {
      "x": -1,
      "y": 5,
      "z": 4,
      "name": "Soil_Clay_Smooth_Black"
    },
    {
      "x": -1,
      "y": 6,
      "z": 4,
      "name": "Soil_Clay_Smooth_Black"
    },
    {
      "x": -1,
      "y": 7,
      "z": 4,
      "name": "Soil_Clay_Smooth_Black",
      "support": 15
    },
    {
      "x": -1,
      "y": 8,
      "z": 4,
      "name": "Soil_Clay_Smooth_Black",
      "support": 15
    },
    {
      "x": -1,
      "y": 9,
      "z": 4,
      "name": "Soil_Clay_Smooth_Black"
    },
    {
      "x": -1,
      "y": 1,
      "z": 5,
      "name": "Soil_Clay_Smooth_Black"
    },
    {
      "x": -1,
      "y": 2,
      "z": 5,
      "name": "Soil_Clay_Smooth_Black",
      "support": 15
    },
    {
      "x": -1,
      "y": 3,
      "z": 5,
      "name": "Soil_Clay_Smooth_Black",
      "support": 15
    },
    {
      "x": -1,
      "y": 4,
      "z": 5,
      "name": "Soil_Clay_Smooth_Black"
    },
    {
      "x": -1,
      "y": 5,
      "z": 5,
      "name": "Soil_Clay_Smooth_Black"
    },
    {
      "x": -1,
      "y": 6,
      "z": 5,
      "name": "Soil_Clay_Smooth_Black"
    },
    {
      "x": -1,
      "y": 7,
      "z": 5,
      "name": "Soil_Clay_Smooth_Black",
      "support": 15
    },
    {
      "x": -1,
      "y": 8,
      "z": 5,
      "name": "Soil_Clay_Smooth_Black",
      "support": 15
    },
    {
      "x": -1,
      "y": 9,
      "z": 5,
      "name": "Soil_Clay_Smooth_Black"
    },
    {
      "x": -1,
      "y": 1,
      "z": 6,
      "name": "Soil_Clay_Smooth_Black"
    },
    {
      "x": -1,
      "y": 2,
      "z": 6,
      "name": "Soil_Clay_Smooth_Black",
      "support": 15
    },
    {
      "x": -1,
      "y": 3,
      "z": 6,
      "name": "Soil_Clay_Smooth_Black",
      "support": 15
    },
    {
      "x": -1,
      "y": 4,
      "z": 6,
      "name": "Soil_Clay_Smooth_Black",
      "support": 15
    },
    {
      "x": -1,
      "y": 5,
      "z": 6,
      "name": "Soil_Clay_Smooth_Black",
      "support": 15
    },
    {
      "x": -1,
      "y": 6,
      "z": 6,
      "name": "Soil_Clay_Smooth_Black",
      "support": 15
    },
    {
      "x": -1,
      "y": 7,
      "z": 6,
      "name": "Soil_Clay_Smooth_Black",
      "support": 15
    },
    {
      "x": -1,
      "y": 8,
      "z": 6,
      "name": "Soil_Clay_Smooth_Black",
      "support": 15
    },
    {
      "x": -1,
      "y": 9,
      "z": 6,
      "name": "Soil_Clay_Smooth_Black"
    },
    {
      "x": -1,
      "y": 1,
      "z": 7,
      "name": "Soil_Clay_Smooth_Black"
    },
    {
      "x": -1,
      "y": 2,
      "z": 7,
      "name": "Soil_Clay_Smooth_Black",
      "support": 15
    },
    {
      "x": -1,
      "y": 3,
      "z": 7,
      "name": "Soil_Clay_Smooth_Black",
      "support": 15
    },
    {
      "x": -1,
      "y": 4,
      "z": 7,
      "name": "Soil_Clay_Smooth_Black",
      "support": 15
    },
    {
      "x": -1,
      "y": 5,
      "z": 7,
      "name": "Soil_Clay_Smooth_Black",
      "support": 15
    },
    {
      "x": -1,
      "y": 6,
      "z": 7,
      "name": "Soil_Clay_Smooth_Black",
      "support": 15
    },
    {
      "x": -1,
      "y": 7,
      "z": 7,
      "name": "Soil_Clay_Smooth_Black",
      "support": 15
    },
    {
      "x": -1,
      "y": 8,
      "z": 7,
      "name": "Soil_Clay_Smooth_Black",
      "support": 15
    },
    {
      "x": -1,
      "y": 9,
      "z": 7,
      "name": "Soil_Clay_Smooth_Black"
    },
    {
      "x": -1,
      "y": 1,
      "z": 8,
      "name": "Soil_Clay_Smooth_Black",
      "support": 15
    },
    {
      "x": -1,
      "y": 2,
      "z": 8,
      "name": "Soil_Clay_Smooth_Black",
      "support": 15
    },
    {
      "x": -1,
      "y": 3,
      "z": 8,
      "name": "Soil_Clay_Smooth_Black",
      "support": 15
    },
    {
      "x": -1,
      "y": 4,
      "z": 8,
      "name": "Soil_Clay_Smooth_Black",
      "support": 15
    },
    {
      "x": -1,
      "y": 5,
      "z": 8,
      "name": "Soil_Clay_Smooth_Black",
      "support": 15
    },
    {
      "x": -1,
      "y": 6,
      "z": 8,
      "name": "Soil_Clay_Smooth_Black",
      "support": 15
    },
    {
      "x": -1,
      "y": 7,
      "z": 8,
      "name": "Soil_Clay_Smooth_Black",
      "support": 15
    },
    {
      "x": -1,
      "y": 8,
      "z": 8,
      "name": "Soil_Clay_Smooth_Black",
      "support": 15
    },
    {
      "x": -1,
      "y": 9,
      "z": 8,
      "name": "Soil_Clay_Smooth_Black"
    },
    {
      "x": -1,
      "y": 1,
      "z": 9,
      "name": "Soil_Clay_Smooth_Black",
      "support": 15
    },
    {
      "x": -1,
      "y": 2,
      "z": 9,
      "name": "Soil_Clay_Smooth_Black",
      "support": 15
    },
    {
      "x": -1,
      "y": 3,
      "z": 9,
      "name": "Soil_Clay_Smooth_Black",
      "support": 15
    },
    {
      "x": -1,
      "y": 4,
      "z": 9,
      "name": "Soil_Clay_Smooth_Black"
    },
    {
      "x": -1,
      "y": 5,
      "z": 9,
      "name": "Soil_Clay_Smooth_Black"
    },
    {
      "x": -1,
      "y": 6,
      "z": 9,
      "name": "Soil_Clay_Smooth_Black"
    },
    {
      "x": -1,
      "y": 7,
      "z": 9,
      "name": "Soil_Clay_Smooth_Black",
      "support": 15
    },
    {
      "x": -1,
      "y": 8,
      "z": 9,
      "name": "Soil_Clay_Smooth_Black",
      "support": 15
    },
    {
      "x": -1,
      "y": 9,
      "z": 9,
      "name": "Soil_Clay_Smooth_Black"
    },
    {
      "x": -1,
      "y": 1,
      "z": 10,
      "name": "Soil_Clay_Smooth_Black",
      "support": 15
    },
    {
      "x": -1,
      "y": 2,
      "z": 10,
      "name": "Soil_Clay_Smooth_Black",
      "support": 15
    },
    {
      "x": -1,
      "y": 3,
      "z": 10,
      "name": "Soil_Clay_Smooth_Black"
    },
    {
      "x": -1,
      "y": 4,
      "z": 10,
      "name": "Soil_Clay_Smooth_Black"
    },
    {
      "x": -1,
      "y": 5,
      "z": 10,
      "name": "Soil_Clay_Smooth_Black"
    },
    {
      "x": -1,
      "y": 6,
      "z": 10,
      "name": "Soil_Clay_Smooth_Black"
    },
    {
      "x": -1,
      "y": 7,
      "z": 10,
      "name": "Soil_Clay_Smooth_Black"
    },
    {
      "x": -1,
      "y": 8,
      "z": 10,
      "name": "Soil_Clay_Smooth_Black",
      "support": 15
    },
    {
      "x": -1,
      "y": 9,
      "z": 10,
      "name": "Soil_Clay_Smooth_Black"
    },
    {
      "x": -1,
      "y": 1,
      "z": 11,
      "name": "Soil_Clay_Smooth_Black"
    },
    {
      "x": -1,
      "y": 2,
      "z": 11,
      "name": "Soil_Clay_Smooth_Black",
      "support": 15
    },
    {
      "x": -1,
      "y": 3,
      "z": 11,
      "name": "Soil_Clay_Smooth_Black",
      "support": 15
    },
    {
      "x": -1,
      "y": 4,
      "z": 11,
      "name": "Soil_Clay_Smooth_Black"
    },
    {
      "x": -1,
      "y": 5,
      "z": 11,
      "name": "Soil_Clay_Smooth_Black"
    },
    {
      "x": -1,
      "y": 6,
      "z": 11,
      "name": "Soil_Clay_Smooth_Black"
    },
    {
      "x": -1,
      "y": 7,
      "z": 11,
      "name": "Soil_Clay_Smooth_Black",
      "support": 15
    },
    {
      "x": -1,
      "y": 8,
      "z": 11,
      "name": "Soil_Clay_Smooth_Black",
      "support": 15
    },
    {
      "x": -1,
      "y": 9,
      "z": 11,
      "name": "Soil_Clay_Smooth_Black"
    },
    {
      "x": -1,
      "y": 1,
      "z": 12,
      "name": "Soil_Clay_Smooth_Black"
    },
    {
      "x": -1,
      "y": 2,
      "z": 12,
      "name": "Soil_Clay_Smooth_Black",
      "support": 15
    },
    {
      "x": -1,
      "y": 3,
      "z": 12,
      "name": "Soil_Clay_Smooth_Black",
      "support": 15
    },
    {
      "x": -1,
      "y": 4,
      "z": 12,
      "name": "Soil_Clay_Smooth_Black",
      "support": 15
    },
    {
      "x": -1,
      "y": 5,
      "z": 12,
      "name": "Soil_Clay_Smooth_Black",
      "support": 15
    },
    {
      "x": -1,
      "y": 6,
      "z": 12,
      "name": "Soil_Clay_Smooth_Black",
      "support": 15
    },
    {
      "x": -1,
      "y": 7,
      "z": 12,
      "name": "Soil_Clay_Smooth_Black",
      "support": 15
    },
    {
      "x": -1,
      "y": 8,
      "z": 12,
      "name": "Soil_Clay_Smooth_Black",
      "support": 15
    },
    {
      "x": -1,
      "y": 9,
      "z": 12,
      "name": "Soil_Clay_Smooth_Black"
    },
    {
      "x": -1,
      "y": 1,
      "z": 13,
      "name": "Soil_Clay_Smooth_Black_Stairs",
      "rotation": 32
    },
    {
      "x": -1,
      "y": 2,
      "z": 13,
      "name": "Soil_Clay_Smooth_Black",
      "support": 15
    },
    {
      "x": -1,
      "y": 3,
      "z": 13,
      "name": "Soil_Clay_Smooth_Black",
      "support": 15
    },
    {
      "x": -1,
      "y": 4,
      "z": 13,
      "name": "Soil_Clay_Smooth_Black"
    },
    {
      "x": -1,
      "y": 5,
      "z": 13,
      "name": "Soil_Clay_Smooth_Black"
    },
    {
      "x": -1,
      "y": 6,
      "z": 13,
      "name": "Soil_Clay_Smooth_Black"
    },
    {
      "x": -1,
      "y": 7,
      "z": 13,
      "name": "Soil_Clay_Smooth_Black",
      "support": 15
    },
    {
      "x": -1,
      "y": 8,
      "z": 13,
      "name": "Soil_Clay_Smooth_Black",
      "support": 15
    },
    {
      "x": -1,
      "y": 9,
      "z": 13,
      "name": "Soil_Clay_Smooth_Black_Stairs"
    },
    {
      "x": 0,
      "y": 0,
      "z": -14,
      "name": "Rock_Gold_Brick_Stairs",
      "rotation": 34
    },
    {
      "x": 0,
      "y": 1,
      "z": -14,
      "name": "Rock_Gold_Brick_Smooth",
      "support": 15
    },
    {
      "x": 0,
      "y": 2,
      "z": -14,
      "name": "Rock_Gold_Brick_Smooth",
      "support": 15
    },
    {
      "x": 0,
      "y": 3,
      "z": -14,
      "name": "Rock_Gold_Brick_Smooth",
      "support": 15
    },
    {
      "x": 0,
      "y": 4,
      "z": -14,
      "name": "Rock_Gold_Brick_Smooth",
      "support": 15
    },
    {
      "x": 0,
      "y": 5,
      "z": -14,
      "name": "Rock_Gold_Brick_Smooth",
      "support": 15
    },
    {
      "x": 0,
      "y": 6,
      "z": -14,
      "name": "Rock_Gold_Brick_Smooth",
      "support": 15
    },
    {
      "x": 0,
      "y": 7,
      "z": -14,
      "name": "Rock_Gold_Brick_Smooth",
      "support": 15
    },
    {
      "x": 0,
      "y": 8,
      "z": -14,
      "name": "Rock_Gold_Brick_Smooth",
      "support": 15
    },
    {
      "x": 0,
      "y": 9,
      "z": -14,
      "name": "Rock_Gold_Brick_Smooth",
      "support": 15
    },
    {
      "x": 0,
      "y": 10,
      "z": -14,
      "name": "Rock_Gold_Brick_Stairs",
      "support": 15,
      "rotation": 2
    },
    {
      "x": 0,
      "y": 0,
      "z": -13,
      "name": "Rock_Gold_Brick_Smooth"
    },
    {
      "x": 0,
      "y": 1,
      "z": -13,
      "name": "Rock_Gold_Brick_Smooth",
      "support": 15
    },
    {
      "x": 0,
      "y": 9,
      "z": -13,
      "name": "Rock_Gold_Brick_Smooth",
      "support": 15
    },
    {
      "x": 0,
      "y": 10,
      "z": -13,
      "name": "Rock_Gold_Brick_Smooth",
      "support": 15
    },
    {
      "x": 0,
      "y": 0,
      "z": -12,
      "name": "Rock_Gold_Brick_Smooth"
    },
    {
      "x": 0,
      "y": 10,
      "z": -12,
      "name": "Rock_Gold_Brick_Smooth"
    },
    {
      "x": 0,
      "y": 0,
      "z": -11,
      "name": "Rock_Gold_Brick_Smooth"
    },
    {
      "x": 0,
      "y": 10,
      "z": -11,
      "name": "Rock_Gold_Brick_Smooth",
      "support": 15
    },
    {
      "x": 0,
      "y": 0,
      "z": -10,
      "name": "Rock_Gold_Brick_Smooth"
    },
    {
      "x": 0,
      "y": 10,
      "z": -10,
      "name": "Rock_Gold_Brick_Smooth",
      "support": 15
    },
    {
      "x": 0,
      "y": 0,
      "z": -9,
      "name": "Rock_Gold_Brick_Smooth"
    },
    {
      "x": 0,
      "y": 10,
      "z": -9,
      "name": "Rock_Gold_Brick_Smooth",
      "support": 15
    },
    {
      "x": 0,
      "y": 0,
      "z": -8,
      "name": "Rock_Gold_Brick_Smooth"
    },
    {
      "x": 0,
      "y": 10,
      "z": -8,
      "name": "Rock_Gold_Brick_Smooth",
      "support": 15
    },
    {
      "x": 0,
      "y": 0,
      "z": -7,
      "name": "Rock_Gold_Brick_Smooth"
    },
    {
      "x": 0,
      "y": 10,
      "z": -7,
      "name": "Rock_Gold_Brick_Smooth",
      "support": 15
    },
    {
      "x": 0,
      "y": 0,
      "z": -6,
      "name": "Rock_Gold_Brick_Smooth"
    },
    {
      "x": 0,
      "y": 10,
      "z": -6,
      "name": "Rock_Gold_Brick_Smooth",
      "support": 15
    },
    {
      "x": 0,
      "y": 0,
      "z": -5,
      "name": "Rock_Gold_Brick_Smooth"
    },
    {
      "x": 0,
      "y": 10,
      "z": -5,
      "name": "Rock_Gold_Brick_Smooth",
      "support": 15
    },
    {
      "x": 0,
      "y": 0,
      "z": -4,
      "name": "Rock_Gold_Brick_Smooth"
    },
    {
      "x": 0,
      "y": 10,
      "z": -4,
      "name": "Rock_Gold_Brick_Smooth",
      "support": 15
    },
    {
      "x": 0,
      "y": 0,
      "z": -3,
      "name": "Rock_Gold_Brick_Smooth"
    },
    {
      "x": 0,
      "y": 10,
      "z": -3,
      "name": "Rock_Gold_Brick_Smooth",
      "support": 15
    },
    {
      "x": 0,
      "y": 0,
      "z": -2,
      "name": "Rock_Gold_Brick_Smooth"
    },
    {
      "x": 0,
      "y": 10,
      "z": -2,
      "name": "Rock_Gold_Brick_Smooth",
      "support": 15
    },
    {
      "x": 0,
      "y": 0,
      "z": -1,
      "name": "Rock_Gold_Brick_Smooth"
    },
    {
      "x": 0,
      "y": 2,
      "z": -1,
      "name": "Soil_Clay_Smooth_Black",
      "support": 15
    },
    {
      "x": 0,
      "y": 10,
      "z": -1,
      "name": "Rock_Gold_Brick_Smooth",
      "support": 15
    },
    {
      "x": 0,
      "y": 0,
      "z": 0,
      "name": "Rock_Gold_Brick_Smooth"
    },
    {
      "x": 0,
      "y": 10,
      "z": 0,
      "name": "Rock_Gold_Brick_Smooth",
      "support": 15
    },
    {
      "x": 0,
      "y": 0,
      "z": 1,
      "name": "Rock_Gold_Brick_Smooth"
    },
    {
      "x": 0,
      "y": 10,
      "z": 1,
      "name": "Rock_Gold_Brick_Smooth",
      "support": 15
    },
    {
      "x": 0,
      "y": 0,
      "z": 2,
      "name": "Rock_Gold_Brick_Smooth"
    },
    {
      "x": 0,
      "y": 10,
      "z": 2,
      "name": "Rock_Gold_Brick_Smooth",
      "support": 15
    },
    {
      "x": 0,
      "y": 0,
      "z": 3,
      "name": "Rock_Gold_Brick_Smooth"
    },
    {
      "x": 0,
      "y": 10,
      "z": 3,
      "name": "Rock_Gold_Brick_Smooth",
      "support": 15
    },
    {
      "x": 0,
      "y": 0,
      "z": 4,
      "name": "Rock_Gold_Brick_Smooth"
    },
    {
      "x": 0,
      "y": 10,
      "z": 4,
      "name": "Rock_Gold_Brick_Smooth",
      "support": 15
    },
    {
      "x": 0,
      "y": 0,
      "z": 5,
      "name": "Rock_Gold_Brick_Smooth"
    },
    {
      "x": 0,
      "y": 10,
      "z": 5,
      "name": "Rock_Gold_Brick_Smooth",
      "support": 15
    },
    {
      "x": 0,
      "y": 0,
      "z": 6,
      "name": "Rock_Gold_Brick_Smooth"
    },
    {
      "x": 0,
      "y": 10,
      "z": 6,
      "name": "Rock_Gold_Brick_Smooth",
      "support": 15
    },
    {
      "x": 0,
      "y": 0,
      "z": 7,
      "name": "Rock_Gold_Brick_Smooth"
    },
    {
      "x": 0,
      "y": 10,
      "z": 7,
      "name": "Rock_Gold_Brick_Smooth",
      "support": 15
    },
    {
      "x": 0,
      "y": 0,
      "z": 8,
      "name": "Rock_Gold_Brick_Smooth"
    },
    {
      "x": 0,
      "y": 10,
      "z": 8,
      "name": "Rock_Gold_Brick_Smooth",
      "support": 15
    },
    {
      "x": 0,
      "y": 0,
      "z": 9,
      "name": "Rock_Gold_Brick_Smooth"
    },
    {
      "x": 0,
      "y": 10,
      "z": 9,
      "name": "Rock_Gold_Brick_Smooth",
      "support": 15
    },
    {
      "x": 0,
      "y": 0,
      "z": 10,
      "name": "Rock_Gold_Brick_Smooth"
    },
    {
      "x": 0,
      "y": 10,
      "z": 10,
      "name": "Rock_Gold_Brick_Smooth",
      "support": 15
    },
    {
      "x": 0,
      "y": 0,
      "z": 11,
      "name": "Rock_Gold_Brick_Smooth"
    },
    {
      "x": 0,
      "y": 10,
      "z": 11,
      "name": "Rock_Gold_Brick_Smooth",
      "support": 15
    },
    {
      "x": 0,
      "y": 0,
      "z": 12,
      "name": "Rock_Gold_Brick_Smooth"
    },
    {
      "x": 0,
      "y": 10,
      "z": 12,
      "name": "Rock_Gold_Brick_Smooth",
      "support": 15
    },
    {
      "x": 0,
      "y": 0,
      "z": 13,
      "name": "Rock_Gold_Brick_Smooth"
    },
    {
      "x": 0,
      "y": 1,
      "z": 13,
      "name": "Rock_Gold_Brick_Smooth",
      "support": 15
    },
    {
      "x": 0,
      "y": 9,
      "z": 13,
      "name": "Rock_Gold_Brick_Smooth",
      "support": 15
    },
    {
      "x": 0,
      "y": 10,
      "z": 13,
      "name": "Rock_Gold_Brick_Smooth",
      "support": 15
    },
    {
      "x": 0,
      "y": 0,
      "z": 14,
      "name": "Rock_Gold_Brick_Stairs",
      "rotation": 32
    },
    {
      "x": 0,
      "y": 1,
      "z": 14,
      "name": "Rock_Gold_Brick_Smooth",
      "support": 15
    },
    {
      "x": 0,
      "y": 2,
      "z": 14,
      "name": "Rock_Gold_Brick_Smooth",
      "support": 15
    },
    {
      "x": 0,
      "y": 3,
      "z": 14,
      "name": "Rock_Gold_Brick_Smooth",
      "support": 15
    },
    {
      "x": 0,
      "y": 4,
      "z": 14,
      "name": "Rock_Gold_Brick_Smooth",
      "support": 15
    },
    {
      "x": 0,
      "y": 5,
      "z": 14,
      "name": "Rock_Gold_Brick_Smooth",
      "support": 15
    },
    {
      "x": 0,
      "y": 6,
      "z": 14,
      "name": "Rock_Gold_Brick_Smooth",
      "support": 15
    },
    {
      "x": 0,
      "y": 7,
      "z": 14,
      "name": "Rock_Gold_Brick_Smooth",
      "support": 15
    },
    {
      "x": 0,
      "y": 8,
      "z": 14,
      "name": "Rock_Gold_Brick_Smooth",
      "support": 15
    },
    {
      "x": 0,
      "y": 9,
      "z": 14,
      "name": "Rock_Gold_Brick_Smooth",
      "support": 15
    },
    {
      "x": 0,
      "y": 10,
      "z": 14,
      "name": "Rock_Gold_Brick_Stairs",
      "support": 15
    },
    {
      "x": 1,
      "y": 1,
      "z": -13,
      "name": "Soil_Clay_Smooth_Black_Stairs",
      "support": 15,
      "rotation": 34
    },
    {
      "x": 1,
      "y": 2,
      "z": -13,
      "name": "Soil_Clay_Smooth_Black",
      "support": 15,
      "rotation": 2
    },
    {
      "x": 1,
      "y": 3,
      "z": -13,
      "name": "Soil_Clay_Smooth_Black",
      "support": 15,
      "rotation": 2
    },
    {
      "x": 1,
      "y": 4,
      "z": -13,
      "name": "Soil_Clay_Smooth_Black",
      "support": 15,
      "rotation": 2
    },
    {
      "x": 1,
      "y": 5,
      "z": -13,
      "name": "Soil_Clay_Smooth_Black",
      "support": 15,
      "rotation": 2
    },
    {
      "x": 1,
      "y": 6,
      "z": -13,
      "name": "Soil_Clay_Smooth_Black",
      "support": 15,
      "rotation": 2
    },
    {
      "x": 1,
      "y": 7,
      "z": -13,
      "name": "Soil_Clay_Smooth_Black",
      "support": 15,
      "rotation": 2
    },
    {
      "x": 1,
      "y": 8,
      "z": -13,
      "name": "Soil_Clay_Smooth_Black",
      "support": 15,
      "rotation": 2
    },
    {
      "x": 1,
      "y": 9,
      "z": -13,
      "name": "Soil_Clay_Smooth_Black_Stairs",
      "support": 15,
      "rotation": 2
    },
    {
      "x": 1,
      "y": 1,
      "z": -12,
      "name": "Soil_Clay_Smooth_Black",
      "rotation": 2
    },
    {
      "x": 1,
      "y": 2,
      "z": -12,
      "name": "Soil_Clay_Smooth_Black",
      "support": 15,
      "rotation": 2
    },
    {
      "x": 1,
      "y": 3,
      "z": -12,
      "name": "Soil_Clay_Smooth_Black",
      "support": 15,
      "rotation": 2
    },
    {
      "x": 1,
      "y": 4,
      "z": -12,
      "name": "Soil_Clay_Smooth_Black",
      "support": 15,
      "rotation": 2
    },
    {
      "x": 1,
      "y": 5,
      "z": -12,
      "name": "Soil_Clay_Smooth_Black",
      "support": 15,
      "rotation": 2
    },
    {
      "x": 1,
      "y": 6,
      "z": -12,
      "name": "Soil_Clay_Smooth_Black",
      "support": 15,
      "rotation": 2
    },
    {
      "x": 1,
      "y": 7,
      "z": -12,
      "name": "Soil_Clay_Smooth_Black",
      "support": 15,
      "rotation": 2
    },
    {
      "x": 1,
      "y": 8,
      "z": -12,
      "name": "Soil_Clay_Smooth_Black",
      "support": 15,
      "rotation": 2
    },
    {
      "x": 1,
      "y": 9,
      "z": -12,
      "name": "Soil_Clay_Smooth_Black",
      "support": 15,
      "rotation": 2
    },
    {
      "x": 1,
      "y": 1,
      "z": -11,
      "name": "Soil_Clay_Smooth_Black",
      "support": 15,
      "rotation": 2
    },
    {
      "x": 1,
      "y": 2,
      "z": -11,
      "name": "Soil_Clay_Smooth_Black",
      "support": 15,
      "rotation": 2
    },
    {
      "x": 1,
      "y": 3,
      "z": -11,
      "name": "Soil_Clay_Smooth_Black",
      "support": 15,
      "rotation": 2
    },
    {
      "x": 1,
      "y": 4,
      "z": -11,
      "name": "Soil_Clay_Smooth_Black",
      "support": 15,
      "rotation": 2
    },
    {
      "x": 1,
      "y": 5,
      "z": -11,
      "name": "Soil_Clay_Smooth_Black",
      "support": 15,
      "rotation": 2
    },
    {
      "x": 1,
      "y": 6,
      "z": -11,
      "name": "Soil_Clay_Smooth_Black",
      "support": 15,
      "rotation": 2
    },
    {
      "x": 1,
      "y": 7,
      "z": -11,
      "name": "Soil_Clay_Smooth_Black",
      "support": 15,
      "rotation": 2
    },
    {
      "x": 1,
      "y": 8,
      "z": -11,
      "name": "Soil_Clay_Smooth_Black",
      "support": 15,
      "rotation": 2
    },
    {
      "x": 1,
      "y": 9,
      "z": -11,
      "name": "Soil_Clay_Smooth_Black",
      "support": 15,
      "rotation": 2
    },
    {
      "x": 1,
      "y": 1,
      "z": -10,
      "name": "Soil_Clay_Smooth_Black",
      "support": 15,
      "rotation": 2
    },
    {
      "x": 1,
      "y": 2,
      "z": -10,
      "name": "Soil_Clay_Smooth_Black",
      "support": 15,
      "rotation": 2
    },
    {
      "x": 1,
      "y": 3,
      "z": -10,
      "name": "Soil_Clay_Smooth_Black",
      "support": 15,
      "rotation": 2
    },
    {
      "x": 1,
      "y": 4,
      "z": -10,
      "name": "Soil_Clay_Smooth_Black",
      "support": 15,
      "rotation": 2
    },
    {
      "x": 1,
      "y": 5,
      "z": -10,
      "name": "Soil_Clay_Smooth_Black",
      "support": 15,
      "rotation": 2
    },
    {
      "x": 1,
      "y": 6,
      "z": -10,
      "name": "Soil_Clay_Smooth_Black",
      "support": 15,
      "rotation": 2
    },
    {
      "x": 1,
      "y": 7,
      "z": -10,
      "name": "Soil_Clay_Smooth_Black",
      "support": 15,
      "rotation": 2
    },
    {
      "x": 1,
      "y": 8,
      "z": -10,
      "name": "Soil_Clay_Smooth_Black",
      "support": 15,
      "rotation": 2
    },
    {
      "x": 1,
      "y": 9,
      "z": -10,
      "name": "Soil_Clay_Smooth_Black",
      "support": 15,
      "rotation": 2
    },
    {
      "x": 1,
      "y": 1,
      "z": -9,
      "name": "Soil_Clay_Smooth_Black",
      "support": 15,
      "rotation": 2
    },
    {
      "x": 1,
      "y": 2,
      "z": -9,
      "name": "Soil_Clay_Smooth_Black",
      "support": 15,
      "rotation": 2
    },
    {
      "x": 1,
      "y": 3,
      "z": -9,
      "name": "Soil_Clay_Smooth_Black",
      "support": 15,
      "rotation": 2
    },
    {
      "x": 1,
      "y": 4,
      "z": -9,
      "name": "Soil_Clay_Smooth_Black",
      "support": 15,
      "rotation": 2
    },
    {
      "x": 1,
      "y": 5,
      "z": -9,
      "name": "Soil_Clay_Smooth_Black",
      "support": 15,
      "rotation": 2
    },
    {
      "x": 1,
      "y": 6,
      "z": -9,
      "name": "Soil_Clay_Smooth_Black",
      "support": 15,
      "rotation": 2
    },
    {
      "x": 1,
      "y": 7,
      "z": -9,
      "name": "Soil_Clay_Smooth_Black",
      "support": 15,
      "rotation": 2
    },
    {
      "x": 1,
      "y": 8,
      "z": -9,
      "name": "Soil_Clay_Smooth_Black",
      "support": 15,
      "rotation": 2
    },
    {
      "x": 1,
      "y": 9,
      "z": -9,
      "name": "Soil_Clay_Smooth_Black",
      "support": 15,
      "rotation": 2
    },
    {
      "x": 1,
      "y": 1,
      "z": -8,
      "name": "Soil_Clay_Smooth_Black",
      "support": 15,
      "rotation": 2
    },
    {
      "x": 1,
      "y": 2,
      "z": -8,
      "name": "Soil_Clay_Smooth_Black",
      "support": 15,
      "rotation": 2
    },
    {
      "x": 1,
      "y": 3,
      "z": -8,
      "name": "Soil_Clay_Smooth_Black",
      "support": 15,
      "rotation": 2
    },
    {
      "x": 1,
      "y": 4,
      "z": -8,
      "name": "Soil_Clay_Smooth_Black",
      "support": 15,
      "rotation": 2
    },
    {
      "x": 1,
      "y": 5,
      "z": -8,
      "name": "Soil_Clay_Smooth_Black",
      "support": 15,
      "rotation": 2
    },
    {
      "x": 1,
      "y": 6,
      "z": -8,
      "name": "Soil_Clay_Smooth_Black",
      "support": 15,
      "rotation": 2
    },
    {
      "x": 1,
      "y": 7,
      "z": -8,
      "name": "Soil_Clay_Smooth_Black",
      "support": 15,
      "rotation": 2
    },
    {
      "x": 1,
      "y": 8,
      "z": -8,
      "name": "Soil_Clay_Smooth_Black",
      "support": 15,
      "rotation": 2
    },
    {
      "x": 1,
      "y": 9,
      "z": -8,
      "name": "Soil_Clay_Smooth_Black",
      "support": 15,
      "rotation": 2
    },
    {
      "x": 1,
      "y": 1,
      "z": -7,
      "name": "Soil_Clay_Smooth_Black",
      "support": 15,
      "rotation": 2
    },
    {
      "x": 1,
      "y": 2,
      "z": -7,
      "name": "Soil_Clay_Smooth_Black",
      "support": 15,
      "rotation": 2
    },
    {
      "x": 1,
      "y": 3,
      "z": -7,
      "name": "Soil_Clay_Smooth_Black",
      "support": 15,
      "rotation": 2
    },
    {
      "x": 1,
      "y": 4,
      "z": -7,
      "name": "Soil_Clay_Smooth_Black",
      "support": 15,
      "rotation": 2
    },
    {
      "x": 1,
      "y": 5,
      "z": -7,
      "name": "Soil_Clay_Smooth_Black",
      "support": 15,
      "rotation": 2
    },
    {
      "x": 1,
      "y": 6,
      "z": -7,
      "name": "Soil_Clay_Smooth_Black",
      "support": 15,
      "rotation": 2
    },
    {
      "x": 1,
      "y": 7,
      "z": -7,
      "name": "Soil_Clay_Smooth_Black",
      "support": 15,
      "rotation": 2
    },
    {
      "x": 1,
      "y": 8,
      "z": -7,
      "name": "Soil_Clay_Smooth_Black",
      "support": 15,
      "rotation": 2
    },
    {
      "x": 1,
      "y": 9,
      "z": -7,
      "name": "Soil_Clay_Smooth_Black",
      "support": 15,
      "rotation": 2
    },
    {
      "x": 1,
      "y": 1,
      "z": -6,
      "name": "Soil_Clay_Smooth_Black",
      "support": 15,
      "rotation": 2
    },
    {
      "x": 1,
      "y": 2,
      "z": -6,
      "name": "Soil_Clay_Smooth_Black",
      "support": 15,
      "rotation": 2
    },
    {
      "x": 1,
      "y": 3,
      "z": -6,
      "name": "Soil_Clay_Smooth_Black",
      "support": 15,
      "rotation": 2
    },
    {
      "x": 1,
      "y": 4,
      "z": -6,
      "name": "Soil_Clay_Smooth_Black",
      "support": 15,
      "rotation": 2
    },
    {
      "x": 1,
      "y": 5,
      "z": -6,
      "name": "Soil_Clay_Smooth_Black",
      "support": 15,
      "rotation": 2
    },
    {
      "x": 1,
      "y": 6,
      "z": -6,
      "name": "Soil_Clay_Smooth_Black",
      "support": 15,
      "rotation": 2
    },
    {
      "x": 1,
      "y": 7,
      "z": -6,
      "name": "Soil_Clay_Smooth_Black",
      "support": 15,
      "rotation": 2
    },
    {
      "x": 1,
      "y": 8,
      "z": -6,
      "name": "Soil_Clay_Smooth_Black",
      "support": 15,
      "rotation": 2
    },
    {
      "x": 1,
      "y": 9,
      "z": -6,
      "name": "Soil_Clay_Smooth_Black",
      "support": 15,
      "rotation": 2
    },
    {
      "x": 1,
      "y": 1,
      "z": -5,
      "name": "Soil_Clay_Smooth_Black",
      "support": 15,
      "rotation": 2
    },
    {
      "x": 1,
      "y": 2,
      "z": -5,
      "name": "Soil_Clay_Smooth_Black",
      "support": 15,
      "rotation": 2
    },
    {
      "x": 1,
      "y": 3,
      "z": -5,
      "name": "Soil_Clay_Smooth_Black",
      "support": 15,
      "rotation": 2
    },
    {
      "x": 1,
      "y": 4,
      "z": -5,
      "name": "Soil_Clay_Smooth_Black",
      "support": 15,
      "rotation": 2
    },
    {
      "x": 1,
      "y": 5,
      "z": -5,
      "name": "Soil_Clay_Smooth_Black",
      "support": 15,
      "rotation": 2
    },
    {
      "x": 1,
      "y": 6,
      "z": -5,
      "name": "Soil_Clay_Smooth_Black",
      "support": 15,
      "rotation": 2
    },
    {
      "x": 1,
      "y": 7,
      "z": -5,
      "name": "Soil_Clay_Smooth_Black",
      "support": 15,
      "rotation": 2
    },
    {
      "x": 1,
      "y": 8,
      "z": -5,
      "name": "Soil_Clay_Smooth_Black",
      "support": 15,
      "rotation": 2
    },
    {
      "x": 1,
      "y": 9,
      "z": -5,
      "name": "Soil_Clay_Smooth_Black",
      "support": 15,
      "rotation": 2
    },
    {
      "x": 1,
      "y": 1,
      "z": -4,
      "name": "Soil_Clay_Smooth_Black",
      "support": 15,
      "rotation": 2
    },
    {
      "x": 1,
      "y": 2,
      "z": -4,
      "name": "Soil_Clay_Smooth_Black",
      "support": 15,
      "rotation": 2
    },
    {
      "x": 1,
      "y": 3,
      "z": -4,
      "name": "Soil_Clay_Smooth_Black",
      "support": 15,
      "rotation": 2
    },
    {
      "x": 1,
      "y": 4,
      "z": -4,
      "name": "Soil_Clay_Smooth_Black",
      "support": 15,
      "rotation": 2
    },
    {
      "x": 1,
      "y": 5,
      "z": -4,
      "name": "Soil_Clay_Smooth_Black",
      "support": 15,
      "rotation": 2
    },
    {
      "x": 1,
      "y": 6,
      "z": -4,
      "name": "Soil_Clay_Smooth_Black",
      "support": 15,
      "rotation": 2
    },
    {
      "x": 1,
      "y": 7,
      "z": -4,
      "name": "Soil_Clay_Smooth_Black",
      "support": 15,
      "rotation": 2
    },
    {
      "x": 1,
      "y": 8,
      "z": -4,
      "name": "Soil_Clay_Smooth_Black",
      "support": 15,
      "rotation": 2
    },
    {
      "x": 1,
      "y": 9,
      "z": -4,
      "name": "Soil_Clay_Smooth_Black",
      "support": 15,
      "rotation": 2
    },
    {
      "x": 1,
      "y": 1,
      "z": -3,
      "name": "Soil_Clay_Smooth_Black",
      "support": 15,
      "rotation": 2
    },
    {
      "x": 1,
      "y": 2,
      "z": -3,
      "name": "Soil_Clay_Smooth_Black",
      "support": 15,
      "rotation": 2
    },
    {
      "x": 1,
      "y": 3,
      "z": -3,
      "name": "Soil_Clay_Smooth_Black",
      "support": 15,
      "rotation": 2
    },
    {
      "x": 1,
      "y": 4,
      "z": -3,
      "name": "Soil_Clay_Smooth_Black",
      "support": 15,
      "rotation": 2
    },
    {
      "x": 1,
      "y": 5,
      "z": -3,
      "name": "Soil_Clay_Smooth_Black",
      "support": 15,
      "rotation": 2
    },
    {
      "x": 1,
      "y": 6,
      "z": -3,
      "name": "Soil_Clay_Smooth_Black",
      "support": 15,
      "rotation": 2
    },
    {
      "x": 1,
      "y": 7,
      "z": -3,
      "name": "Soil_Clay_Smooth_Black",
      "support": 15,
      "rotation": 2
    },
    {
      "x": 1,
      "y": 8,
      "z": -3,
      "name": "Soil_Clay_Smooth_Black",
      "support": 15,
      "rotation": 2
    },
    {
      "x": 1,
      "y": 9,
      "z": -3,
      "name": "Soil_Clay_Smooth_Black",
      "support": 15,
      "rotation": 2
    },
    {
      "x": 1,
      "y": 1,
      "z": -2,
      "name": "Soil_Clay_Smooth_Black",
      "support": 15,
      "rotation": 2
    },
    {
      "x": 1,
      "y": 2,
      "z": -2,
      "name": "Soil_Clay_Smooth_Black",
      "support": 15,
      "rotation": 2
    },
    {
      "x": 1,
      "y": 3,
      "z": -2,
      "name": "Soil_Clay_Smooth_Black",
      "support": 15,
      "rotation": 2
    },
    {
      "x": 1,
      "y": 4,
      "z": -2,
      "name": "Soil_Clay_Smooth_Black",
      "support": 15,
      "rotation": 2
    },
    {
      "x": 1,
      "y": 5,
      "z": -2,
      "name": "Soil_Clay_Smooth_Black",
      "support": 15,
      "rotation": 2
    },
    {
      "x": 1,
      "y": 6,
      "z": -2,
      "name": "Soil_Clay_Smooth_Black",
      "support": 15,
      "rotation": 2
    },
    {
      "x": 1,
      "y": 7,
      "z": -2,
      "name": "Soil_Clay_Smooth_Black",
      "support": 15,
      "rotation": 2
    },
    {
      "x": 1,
      "y": 8,
      "z": -2,
      "name": "Soil_Clay_Smooth_Black",
      "support": 15,
      "rotation": 2
    },
    {
      "x": 1,
      "y": 9,
      "z": -2,
      "name": "Soil_Clay_Smooth_Black",
      "support": 15,
      "rotation": 2
    },
    {
      "x": 1,
      "y": 1,
      "z": -1,
      "name": "Soil_Clay_Smooth_Black",
      "support": 15,
      "rotation": 2
    },
    {
      "x": 1,
      "y": 2,
      "z": -1,
      "name": "Soil_Clay_Smooth_Black",
      "support": 15,
      "rotation": 2
    },
    {
      "x": 1,
      "y": 3,
      "z": -1,
      "name": "Soil_Clay_Smooth_Black",
      "support": 15,
      "rotation": 2
    },
    {
      "x": 1,
      "y": 4,
      "z": -1,
      "name": "Soil_Clay_Smooth_Black",
      "support": 15,
      "rotation": 2
    },
    {
      "x": 1,
      "y": 5,
      "z": -1,
      "name": "Soil_Clay_Smooth_Black",
      "support": 15,
      "rotation": 2
    },
    {
      "x": 1,
      "y": 6,
      "z": -1,
      "name": "Soil_Clay_Smooth_Black",
      "support": 15,
      "rotation": 2
    },
    {
      "x": 1,
      "y": 7,
      "z": -1,
      "name": "Soil_Clay_Smooth_Black",
      "support": 15,
      "rotation": 2
    },
    {
      "x": 1,
      "y": 8,
      "z": -1,
      "name": "Soil_Clay_Smooth_Black",
      "support": 15,
      "rotation": 2
    },
    {
      "x": 1,
      "y": 9,
      "z": -1,
      "name": "Soil_Clay_Smooth_Black",
      "support": 15,
      "rotation": 2
    },
    {
      "x": 1,
      "y": 1,
      "z": 0,
      "name": "Soil_Clay_Smooth_Black",
      "support": 15,
      "rotation": 2
    },
    {
      "x": 1,
      "y": 2,
      "z": 0,
      "name": "Soil_Clay_Smooth_Black",
      "support": 15,
      "rotation": 2
    },
    {
      "x": 1,
      "y": 3,
      "z": 0,
      "name": "Soil_Clay_Smooth_Black",
      "support": 15,
      "rotation": 2
    },
    {
      "x": 1,
      "y": 4,
      "z": 0,
      "name": "Soil_Clay_Smooth_Black",
      "support": 15,
      "rotation": 2
    },
    {
      "x": 1,
      "y": 5,
      "z": 0,
      "name": "Soil_Clay_Smooth_Black",
      "support": 15,
      "rotation": 2
    },
    {
      "x": 1,
      "y": 6,
      "z": 0,
      "name": "Soil_Clay_Smooth_Black",
      "support": 15,
      "rotation": 2
    },
    {
      "x": 1,
      "y": 7,
      "z": 0,
      "name": "Soil_Clay_Smooth_Black",
      "support": 15,
      "rotation": 2
    },
    {
      "x": 1,
      "y": 8,
      "z": 0,
      "name": "Soil_Clay_Smooth_Black",
      "support": 15,
      "rotation": 2
    },
    {
      "x": 1,
      "y": 9,
      "z": 0,
      "name": "Soil_Clay_Smooth_Black",
      "support": 15,
      "rotation": 2
    },
    {
      "x": 1,
      "y": 1,
      "z": 1,
      "name": "Soil_Clay_Smooth_Black",
      "support": 15,
      "rotation": 2
    },
    {
      "x": 1,
      "y": 2,
      "z": 1,
      "name": "Soil_Clay_Smooth_Black",
      "support": 15,
      "rotation": 2
    },
    {
      "x": 1,
      "y": 3,
      "z": 1,
      "name": "Soil_Clay_Smooth_Black",
      "support": 15,
      "rotation": 2
    },
    {
      "x": 1,
      "y": 4,
      "z": 1,
      "name": "Soil_Clay_Smooth_Black",
      "support": 15,
      "rotation": 2
    },
    {
      "x": 1,
      "y": 5,
      "z": 1,
      "name": "Soil_Clay_Smooth_Black",
      "support": 15,
      "rotation": 2
    },
    {
      "x": 1,
      "y": 6,
      "z": 1,
      "name": "Soil_Clay_Smooth_Black",
      "support": 15,
      "rotation": 2
    },
    {
      "x": 1,
      "y": 7,
      "z": 1,
      "name": "Soil_Clay_Smooth_Black",
      "support": 15,
      "rotation": 2
    },
    {
      "x": 1,
      "y": 8,
      "z": 1,
      "name": "Soil_Clay_Smooth_Black",
      "support": 15,
      "rotation": 2
    },
    {
      "x": 1,
      "y": 9,
      "z": 1,
      "name": "Soil_Clay_Smooth_Black",
      "support": 15,
      "rotation": 2
    },
    {
      "x": 1,
      "y": 1,
      "z": 2,
      "name": "Soil_Clay_Smooth_Black",
      "support": 15,
      "rotation": 2
    },
    {
      "x": 1,
      "y": 2,
      "z": 2,
      "name": "Soil_Clay_Smooth_Black",
      "support": 15,
      "rotation": 2
    },
    {
      "x": 1,
      "y": 3,
      "z": 2,
      "name": "Soil_Clay_Smooth_Black",
      "support": 15,
      "rotation": 2
    },
    {
      "x": 1,
      "y": 4,
      "z": 2,
      "name": "Soil_Clay_Smooth_Black",
      "support": 15,
      "rotation": 2
    },
    {
      "x": 1,
      "y": 5,
      "z": 2,
      "name": "Soil_Clay_Smooth_Black",
      "support": 15,
      "rotation": 2
    },
    {
      "x": 1,
      "y": 6,
      "z": 2,
      "name": "Soil_Clay_Smooth_Black",
      "support": 15,
      "rotation": 2
    },
    {
      "x": 1,
      "y": 7,
      "z": 2,
      "name": "Soil_Clay_Smooth_Black",
      "support": 15,
      "rotation": 2
    },
    {
      "x": 1,
      "y": 8,
      "z": 2,
      "name": "Soil_Clay_Smooth_Black",
      "support": 15,
      "rotation": 2
    },
    {
      "x": 1,
      "y": 9,
      "z": 2,
      "name": "Soil_Clay_Smooth_Black",
      "support": 15,
      "rotation": 2
    },
    {
      "x": 1,
      "y": 1,
      "z": 3,
      "name": "Soil_Clay_Smooth_Black",
      "support": 15,
      "rotation": 2
    },
    {
      "x": 1,
      "y": 2,
      "z": 3,
      "name": "Soil_Clay_Smooth_Black",
      "support": 15,
      "rotation": 2
    },
    {
      "x": 1,
      "y": 3,
      "z": 3,
      "name": "Soil_Clay_Smooth_Black",
      "support": 15,
      "rotation": 2
    },
    {
      "x": 1,
      "y": 4,
      "z": 3,
      "name": "Soil_Clay_Smooth_Black",
      "support": 15,
      "rotation": 2
    },
    {
      "x": 1,
      "y": 5,
      "z": 3,
      "name": "Soil_Clay_Smooth_Black",
      "support": 15,
      "rotation": 2
    },
    {
      "x": 1,
      "y": 6,
      "z": 3,
      "name": "Soil_Clay_Smooth_Black",
      "support": 15,
      "rotation": 2
    },
    {
      "x": 1,
      "y": 7,
      "z": 3,
      "name": "Soil_Clay_Smooth_Black",
      "support": 15,
      "rotation": 2
    },
    {
      "x": 1,
      "y": 8,
      "z": 3,
      "name": "Soil_Clay_Smooth_Black",
      "support": 15,
      "rotation": 2
    },
    {
      "x": 1,
      "y": 9,
      "z": 3,
      "name": "Soil_Clay_Smooth_Black",
      "support": 15,
      "rotation": 2
    },
    {
      "x": 1,
      "y": 1,
      "z": 4,
      "name": "Soil_Clay_Smooth_Black",
      "support": 15,
      "rotation": 2
    },
    {
      "x": 1,
      "y": 2,
      "z": 4,
      "name": "Soil_Clay_Smooth_Black",
      "support": 15,
      "rotation": 2
    },
    {
      "x": 1,
      "y": 3,
      "z": 4,
      "name": "Soil_Clay_Smooth_Black",
      "support": 15,
      "rotation": 2
    },
    {
      "x": 1,
      "y": 4,
      "z": 4,
      "name": "Soil_Clay_Smooth_Black",
      "support": 15,
      "rotation": 2
    },
    {
      "x": 1,
      "y": 5,
      "z": 4,
      "name": "Soil_Clay_Smooth_Black",
      "support": 15,
      "rotation": 2
    },
    {
      "x": 1,
      "y": 6,
      "z": 4,
      "name": "Soil_Clay_Smooth_Black",
      "support": 15,
      "rotation": 2
    },
    {
      "x": 1,
      "y": 7,
      "z": 4,
      "name": "Soil_Clay_Smooth_Black",
      "support": 15,
      "rotation": 2
    },
    {
      "x": 1,
      "y": 8,
      "z": 4,
      "name": "Soil_Clay_Smooth_Black",
      "support": 15,
      "rotation": 2
    },
    {
      "x": 1,
      "y": 9,
      "z": 4,
      "name": "Soil_Clay_Smooth_Black",
      "support": 15,
      "rotation": 2
    },
    {
      "x": 1,
      "y": 1,
      "z": 5,
      "name": "Soil_Clay_Smooth_Black",
      "support": 15,
      "rotation": 2
    },
    {
      "x": 1,
      "y": 2,
      "z": 5,
      "name": "Soil_Clay_Smooth_Black",
      "support": 15,
      "rotation": 2
    },
    {
      "x": 1,
      "y": 3,
      "z": 5,
      "name": "Soil_Clay_Smooth_Black",
      "support": 15,
      "rotation": 2
    },
    {
      "x": 1,
      "y": 4,
      "z": 5,
      "name": "Soil_Clay_Smooth_Black",
      "support": 15,
      "rotation": 2
    },
    {
      "x": 1,
      "y": 5,
      "z": 5,
      "name": "Soil_Clay_Smooth_Black",
      "support": 15,
      "rotation": 2
    },
    {
      "x": 1,
      "y": 6,
      "z": 5,
      "name": "Soil_Clay_Smooth_Black",
      "support": 15,
      "rotation": 2
    },
    {
      "x": 1,
      "y": 7,
      "z": 5,
      "name": "Soil_Clay_Smooth_Black",
      "support": 15,
      "rotation": 2
    },
    {
      "x": 1,
      "y": 8,
      "z": 5,
      "name": "Soil_Clay_Smooth_Black",
      "support": 15,
      "rotation": 2
    },
    {
      "x": 1,
      "y": 9,
      "z": 5,
      "name": "Soil_Clay_Smooth_Black",
      "support": 15,
      "rotation": 2
    },
    {
      "x": 1,
      "y": 1,
      "z": 6,
      "name": "Soil_Clay_Smooth_Black",
      "support": 15,
      "rotation": 2
    },
    {
      "x": 1,
      "y": 2,
      "z": 6,
      "name": "Soil_Clay_Smooth_Black",
      "support": 15,
      "rotation": 2
    },
    {
      "x": 1,
      "y": 3,
      "z": 6,
      "name": "Soil_Clay_Smooth_Black",
      "support": 15,
      "rotation": 2
    },
    {
      "x": 1,
      "y": 4,
      "z": 6,
      "name": "Soil_Clay_Smooth_Black",
      "support": 15,
      "rotation": 2
    },
    {
      "x": 1,
      "y": 5,
      "z": 6,
      "name": "Soil_Clay_Smooth_Black",
      "support": 15,
      "rotation": 2
    },
    {
      "x": 1,
      "y": 6,
      "z": 6,
      "name": "Soil_Clay_Smooth_Black",
      "support": 15,
      "rotation": 2
    },
    {
      "x": 1,
      "y": 7,
      "z": 6,
      "name": "Soil_Clay_Smooth_Black",
      "support": 15,
      "rotation": 2
    },
    {
      "x": 1,
      "y": 8,
      "z": 6,
      "name": "Soil_Clay_Smooth_Black",
      "support": 15,
      "rotation": 2
    },
    {
      "x": 1,
      "y": 9,
      "z": 6,
      "name": "Soil_Clay_Smooth_Black",
      "support": 15,
      "rotation": 2
    },
    {
      "x": 1,
      "y": 1,
      "z": 7,
      "name": "Soil_Clay_Smooth_Black",
      "support": 15,
      "rotation": 2
    },
    {
      "x": 1,
      "y": 2,
      "z": 7,
      "name": "Soil_Clay_Smooth_Black",
      "support": 15,
      "rotation": 2
    },
    {
      "x": 1,
      "y": 3,
      "z": 7,
      "name": "Soil_Clay_Smooth_Black",
      "support": 15,
      "rotation": 2
    },
    {
      "x": 1,
      "y": 4,
      "z": 7,
      "name": "Soil_Clay_Smooth_Black",
      "support": 15,
      "rotation": 2
    },
    {
      "x": 1,
      "y": 5,
      "z": 7,
      "name": "Soil_Clay_Smooth_Black",
      "support": 15,
      "rotation": 2
    },
    {
      "x": 1,
      "y": 6,
      "z": 7,
      "name": "Soil_Clay_Smooth_Black",
      "support": 15,
      "rotation": 2
    },
    {
      "x": 1,
      "y": 7,
      "z": 7,
      "name": "Soil_Clay_Smooth_Black",
      "support": 15,
      "rotation": 2
    },
    {
      "x": 1,
      "y": 8,
      "z": 7,
      "name": "Soil_Clay_Smooth_Black",
      "support": 15,
      "rotation": 2
    },
    {
      "x": 1,
      "y": 9,
      "z": 7,
      "name": "Soil_Clay_Smooth_Black",
      "support": 15,
      "rotation": 2
    },
    {
      "x": 1,
      "y": 1,
      "z": 8,
      "name": "Soil_Clay_Smooth_Black",
      "support": 15,
      "rotation": 2
    },
    {
      "x": 1,
      "y": 2,
      "z": 8,
      "name": "Soil_Clay_Smooth_Black",
      "support": 15,
      "rotation": 2
    },
    {
      "x": 1,
      "y": 3,
      "z": 8,
      "name": "Soil_Clay_Smooth_Black",
      "support": 15,
      "rotation": 2
    },
    {
      "x": 1,
      "y": 4,
      "z": 8,
      "name": "Soil_Clay_Smooth_Black",
      "support": 15,
      "rotation": 2
    },
    {
      "x": 1,
      "y": 5,
      "z": 8,
      "name": "Soil_Clay_Smooth_Black",
      "support": 15,
      "rotation": 2
    },
    {
      "x": 1,
      "y": 6,
      "z": 8,
      "name": "Soil_Clay_Smooth_Black",
      "support": 15,
      "rotation": 2
    },
    {
      "x": 1,
      "y": 7,
      "z": 8,
      "name": "Soil_Clay_Smooth_Black",
      "support": 15,
      "rotation": 2
    },
    {
      "x": 1,
      "y": 8,
      "z": 8,
      "name": "Soil_Clay_Smooth_Black",
      "support": 15,
      "rotation": 2
    },
    {
      "x": 1,
      "y": 9,
      "z": 8,
      "name": "Soil_Clay_Smooth_Black",
      "support": 15,
      "rotation": 2
    },
    {
      "x": 1,
      "y": 1,
      "z": 9,
      "name": "Soil_Clay_Smooth_Black",
      "support": 15,
      "rotation": 2
    },
    {
      "x": 1,
      "y": 2,
      "z": 9,
      "name": "Soil_Clay_Smooth_Black",
      "support": 15,
      "rotation": 2
    },
    {
      "x": 1,
      "y": 3,
      "z": 9,
      "name": "Soil_Clay_Smooth_Black",
      "support": 15,
      "rotation": 2
    },
    {
      "x": 1,
      "y": 4,
      "z": 9,
      "name": "Soil_Clay_Smooth_Black",
      "support": 15,
      "rotation": 2
    },
    {
      "x": 1,
      "y": 5,
      "z": 9,
      "name": "Soil_Clay_Smooth_Black",
      "support": 15,
      "rotation": 2
    },
    {
      "x": 1,
      "y": 6,
      "z": 9,
      "name": "Soil_Clay_Smooth_Black",
      "support": 15,
      "rotation": 2
    },
    {
      "x": 1,
      "y": 7,
      "z": 9,
      "name": "Soil_Clay_Smooth_Black",
      "rotation": 2
    },
    {
      "x": 1,
      "y": 8,
      "z": 9,
      "name": "Soil_Clay_Smooth_Black",
      "support": 15,
      "rotation": 2
    },
    {
      "x": 1,
      "y": 9,
      "z": 9,
      "name": "Soil_Clay_Smooth_Black",
      "support": 15,
      "rotation": 2
    },
    {
      "x": 1,
      "y": 1,
      "z": 10,
      "name": "Soil_Clay_Smooth_Black",
      "support": 15,
      "rotation": 2
    },
    {
      "x": 1,
      "y": 2,
      "z": 10,
      "name": "Soil_Clay_Smooth_Black",
      "support": 15,
      "rotation": 2
    },
    {
      "x": 1,
      "y": 3,
      "z": 10,
      "name": "Soil_Clay_Smooth_Black",
      "support": 15,
      "rotation": 2
    },
    {
      "x": 1,
      "y": 4,
      "z": 10,
      "name": "Soil_Clay_Smooth_Black",
      "support": 15,
      "rotation": 2
    },
    {
      "x": 1,
      "y": 5,
      "z": 10,
      "name": "Soil_Clay_Smooth_Black",
      "support": 15,
      "rotation": 2
    },
    {
      "x": 1,
      "y": 6,
      "z": 10,
      "name": "Soil_Clay_Smooth_Black",
      "support": 15,
      "rotation": 2
    },
    {
      "x": 1,
      "y": 7,
      "z": 10,
      "name": "Soil_Clay_Smooth_Black",
      "support": 15,
      "rotation": 2
    },
    {
      "x": 1,
      "y": 8,
      "z": 10,
      "name": "Soil_Clay_Smooth_Black",
      "support": 15,
      "rotation": 2
    },
    {
      "x": 1,
      "y": 9,
      "z": 10,
      "name": "Soil_Clay_Smooth_Black",
      "support": 15,
      "rotation": 2
    },
    {
      "x": 1,
      "y": 1,
      "z": 11,
      "name": "Soil_Clay_Smooth_Black",
      "support": 15,
      "rotation": 2
    },
    {
      "x": 1,
      "y": 2,
      "z": 11,
      "name": "Soil_Clay_Smooth_Black",
      "support": 15,
      "rotation": 2
    },
    {
      "x": 1,
      "y": 3,
      "z": 11,
      "name": "Soil_Clay_Smooth_Black",
      "support": 15,
      "rotation": 2
    },
    {
      "x": 1,
      "y": 4,
      "z": 11,
      "name": "Soil_Clay_Smooth_Black",
      "support": 15,
      "rotation": 2
    },
    {
      "x": 1,
      "y": 5,
      "z": 11,
      "name": "Soil_Clay_Smooth_Black",
      "support": 15,
      "rotation": 2
    },
    {
      "x": 1,
      "y": 6,
      "z": 11,
      "name": "Soil_Clay_Smooth_Black",
      "support": 15,
      "rotation": 2
    },
    {
      "x": 1,
      "y": 7,
      "z": 11,
      "name": "Soil_Clay_Smooth_Black",
      "support": 15,
      "rotation": 2
    },
    {
      "x": 1,
      "y": 8,
      "z": 11,
      "name": "Soil_Clay_Smooth_Black",
      "support": 15,
      "rotation": 2
    },
    {
      "x": 1,
      "y": 9,
      "z": 11,
      "name": "Soil_Clay_Smooth_Black",
      "support": 15,
      "rotation": 2
    },
    {
      "x": 1,
      "y": 1,
      "z": 12,
      "name": "Soil_Clay_Smooth_Black",
      "support": 15,
      "rotation": 2
    },
    {
      "x": 1,
      "y": 2,
      "z": 12,
      "name": "Soil_Clay_Smooth_Black",
      "support": 15,
      "rotation": 2
    },
    {
      "x": 1,
      "y": 3,
      "z": 12,
      "name": "Soil_Clay_Smooth_Black",
      "support": 15,
      "rotation": 2
    },
    {
      "x": 1,
      "y": 4,
      "z": 12,
      "name": "Soil_Clay_Smooth_Black",
      "support": 15,
      "rotation": 2
    },
    {
      "x": 1,
      "y": 5,
      "z": 12,
      "name": "Soil_Clay_Smooth_Black",
      "support": 15,
      "rotation": 2
    },
    {
      "x": 1,
      "y": 6,
      "z": 12,
      "name": "Soil_Clay_Smooth_Black",
      "support": 15,
      "rotation": 2
    },
    {
      "x": 1,
      "y": 7,
      "z": 12,
      "name": "Soil_Clay_Smooth_Black",
      "support": 15,
      "rotation": 2
    },
    {
      "x": 1,
      "y": 8,
      "z": 12,
      "name": "Soil_Clay_Smooth_Black",
      "support": 15,
      "rotation": 2
    },
    {
      "x": 1,
      "y": 9,
      "z": 12,
      "name": "Soil_Clay_Smooth_Black",
      "support": 15,
      "rotation": 2
    },
    {
      "x": 1,
      "y": 1,
      "z": 13,
      "name": "Soil_Clay_Smooth_Black_Stairs",
      "support": 15,
      "rotation": 32
    },
    {
      "x": 1,
      "y": 2,
      "z": 13,
      "name": "Soil_Clay_Smooth_Black",
      "support": 15,
      "rotation": 2
    },
    {
      "x": 1,
      "y": 3,
      "z": 13,
      "name": "Soil_Clay_Smooth_Black",
      "support": 15,
      "rotation": 2
    },
    {
      "x": 1,
      "y": 4,
      "z": 13,
      "name": "Soil_Clay_Smooth_Black",
      "support": 15,
      "rotation": 2
    },
    {
      "x": 1,
      "y": 5,
      "z": 13,
      "name": "Soil_Clay_Smooth_Black",
      "support": 15,
      "rotation": 2
    },
    {
      "x": 1,
      "y": 6,
      "z": 13,
      "name": "Soil_Clay_Smooth_Black",
      "support": 15,
      "rotation": 2
    },
    {
      "x": 1,
      "y": 7,
      "z": 13,
      "name": "Soil_Clay_Smooth_Black",
      "support": 15,
      "rotation": 2
    },
    {
      "x": 1,
      "y": 8,
      "z": 13,
      "name": "Soil_Clay_Smooth_Black",
      "support": 15,
      "rotation": 2
    },
    {
      "x": 1,
      "y": 9,
      "z": 13,
      "name": "Soil_Clay_Smooth_Black_Stairs",
      "support": 15
    },
    {
      "x": 2,
      "y": 3,
      "z": 0,
      "name": "Build_Lightsource_White",
      "support": 15,
      "rotation": 4
    },
    {
      "x": 2,
      "y": 6,
      "z": 0,
      "name": "Build_Lightsource_White",
      "support": 15,
      "rotation": 4
    }
  ],
  "fluids": [
    {
      "x": -2,
      "y": 3,
      "z": 0,
      "name": "Empty",
      "level": 0
    },
    {
      "x": -2,
      "y": 6,
      "z": 0,
      "name": "Empty",
      "level": 0
    },
    {
      "x": -1,
      "y": 1,
      "z": -13,
      "name": "Empty",
      "level": 0
    },
    {
      "x": -1,
      "y": 2,
      "z": -13,
      "name": "Empty",
      "level": 0
    },
    {
      "x": -1,
      "y": 3,
      "z": -13,
      "name": "Empty",
      "level": 0
    },
    {
      "x": -1,
      "y": 4,
      "z": -13,
      "name": "Empty",
      "level": 0
    },
    {
      "x": -1,
      "y": 5,
      "z": -13,
      "name": "Empty",
      "level": 0
    },
    {
      "x": -1,
      "y": 6,
      "z": -13,
      "name": "Empty",
      "level": 0
    },
    {
      "x": -1,
      "y": 7,
      "z": -13,
      "name": "Empty",
      "level": 0
    },
    {
      "x": -1,
      "y": 8,
      "z": -13,
      "name": "Empty",
      "level": 0
    },
    {
      "x": -1,
      "y": 9,
      "z": -13,
      "name": "Empty",
      "level": 0
    },
    {
      "x": -1,
      "y": 1,
      "z": -12,
      "name": "Empty",
      "level": 0
    },
    {
      "x": -1,
      "y": 2,
      "z": -12,
      "name": "Empty",
      "level": 0
    },
    {
      "x": -1,
      "y": 3,
      "z": -12,
      "name": "Empty",
      "level": 0
    },
    {
      "x": -1,
      "y": 4,
      "z": -12,
      "name": "Empty",
      "level": 0
    },
    {
      "x": -1,
      "y": 5,
      "z": -12,
      "name": "Empty",
      "level": 0
    },
    {
      "x": -1,
      "y": 6,
      "z": -12,
      "name": "Empty",
      "level": 0
    },
    {
      "x": -1,
      "y": 7,
      "z": -12,
      "name": "Empty",
      "level": 0
    },
    {
      "x": -1,
      "y": 8,
      "z": -12,
      "name": "Empty",
      "level": 0
    },
    {
      "x": -1,
      "y": 9,
      "z": -12,
      "name": "Empty",
      "level": 0
    },
    {
      "x": -1,
      "y": 1,
      "z": -11,
      "name": "Empty",
      "level": 0
    },
    {
      "x": -1,
      "y": 2,
      "z": -11,
      "name": "Empty",
      "level": 0
    },
    {
      "x": -1,
      "y": 3,
      "z": -11,
      "name": "Empty",
      "level": 0
    },
    {
      "x": -1,
      "y": 4,
      "z": -11,
      "name": "Empty",
      "level": 0
    },
    {
      "x": -1,
      "y": 5,
      "z": -11,
      "name": "Empty",
      "level": 0
    },
    {
      "x": -1,
      "y": 6,
      "z": -11,
      "name": "Empty",
      "level": 0
    },
    {
      "x": -1,
      "y": 7,
      "z": -11,
      "name": "Empty",
      "level": 0
    },
    {
      "x": -1,
      "y": 8,
      "z": -11,
      "name": "Empty",
      "level": 0
    },
    {
      "x": -1,
      "y": 9,
      "z": -11,
      "name": "Empty",
      "level": 0
    },
    {
      "x": -1,
      "y": 1,
      "z": -10,
      "name": "Empty",
      "level": 0
    },
    {
      "x": -1,
      "y": 2,
      "z": -10,
      "name": "Empty",
      "level": 0
    },
    {
      "x": -1,
      "y": 3,
      "z": -10,
      "name": "Empty",
      "level": 0
    },
    {
      "x": -1,
      "y": 4,
      "z": -10,
      "name": "Empty",
      "level": 0
    },
    {
      "x": -1,
      "y": 5,
      "z": -10,
      "name": "Empty",
      "level": 0
    },
    {
      "x": -1,
      "y": 6,
      "z": -10,
      "name": "Empty",
      "level": 0
    },
    {
      "x": -1,
      "y": 7,
      "z": -10,
      "name": "Empty",
      "level": 0
    },
    {
      "x": -1,
      "y": 8,
      "z": -10,
      "name": "Empty",
      "level": 0
    },
    {
      "x": -1,
      "y": 9,
      "z": -10,
      "name": "Empty",
      "level": 0
    },
    {
      "x": -1,
      "y": 1,
      "z": -9,
      "name": "Empty",
      "level": 0
    },
    {
      "x": -1,
      "y": 2,
      "z": -9,
      "name": "Empty",
      "level": 0
    },
    {
      "x": -1,
      "y": 3,
      "z": -9,
      "name": "Empty",
      "level": 0
    },
    {
      "x": -1,
      "y": 4,
      "z": -9,
      "name": "Empty",
      "level": 0
    },
    {
      "x": -1,
      "y": 5,
      "z": -9,
      "name": "Empty",
      "level": 0
    },
    {
      "x": -1,
      "y": 6,
      "z": -9,
      "name": "Empty",
      "level": 0
    },
    {
      "x": -1,
      "y": 7,
      "z": -9,
      "name": "Empty",
      "level": 0
    },
    {
      "x": -1,
      "y": 8,
      "z": -9,
      "name": "Empty",
      "level": 0
    },
    {
      "x": -1,
      "y": 9,
      "z": -9,
      "name": "Empty",
      "level": 0
    },
    {
      "x": -1,
      "y": 1,
      "z": -8,
      "name": "Empty",
      "level": 0
    },
    {
      "x": -1,
      "y": 2,
      "z": -8,
      "name": "Empty",
      "level": 0
    },
    {
      "x": -1,
      "y": 3,
      "z": -8,
      "name": "Empty",
      "level": 0
    },
    {
      "x": -1,
      "y": 4,
      "z": -8,
      "name": "Empty",
      "level": 0
    },
    {
      "x": -1,
      "y": 5,
      "z": -8,
      "name": "Empty",
      "level": 0
    },
    {
      "x": -1,
      "y": 6,
      "z": -8,
      "name": "Empty",
      "level": 0
    },
    {
      "x": -1,
      "y": 7,
      "z": -8,
      "name": "Empty",
      "level": 0
    },
    {
      "x": -1,
      "y": 8,
      "z": -8,
      "name": "Empty",
      "level": 0
    },
    {
      "x": -1,
      "y": 9,
      "z": -8,
      "name": "Empty",
      "level": 0
    },
    {
      "x": -1,
      "y": 1,
      "z": -7,
      "name": "Empty",
      "level": 0
    },
    {
      "x": -1,
      "y": 2,
      "z": -7,
      "name": "Empty",
      "level": 0
    },
    {
      "x": -1,
      "y": 3,
      "z": -7,
      "name": "Empty",
      "level": 0
    },
    {
      "x": -1,
      "y": 4,
      "z": -7,
      "name": "Empty",
      "level": 0
    },
    {
      "x": -1,
      "y": 5,
      "z": -7,
      "name": "Empty",
      "level": 0
    },
    {
      "x": -1,
      "y": 6,
      "z": -7,
      "name": "Empty",
      "level": 0
    },
    {
      "x": -1,
      "y": 7,
      "z": -7,
      "name": "Empty",
      "level": 0
    },
    {
      "x": -1,
      "y": 8,
      "z": -7,
      "name": "Empty",
      "level": 0
    },
    {
      "x": -1,
      "y": 9,
      "z": -7,
      "name": "Empty",
      "level": 0
    },
    {
      "x": -1,
      "y": 1,
      "z": -6,
      "name": "Empty",
      "level": 0
    },
    {
      "x": -1,
      "y": 2,
      "z": -6,
      "name": "Empty",
      "level": 0
    },
    {
      "x": -1,
      "y": 3,
      "z": -6,
      "name": "Empty",
      "level": 0
    },
    {
      "x": -1,
      "y": 4,
      "z": -6,
      "name": "Empty",
      "level": 0
    },
    {
      "x": -1,
      "y": 5,
      "z": -6,
      "name": "Empty",
      "level": 0
    },
    {
      "x": -1,
      "y": 6,
      "z": -6,
      "name": "Empty",
      "level": 0
    },
    {
      "x": -1,
      "y": 7,
      "z": -6,
      "name": "Empty",
      "level": 0
    },
    {
      "x": -1,
      "y": 8,
      "z": -6,
      "name": "Empty",
      "level": 0
    },
    {
      "x": -1,
      "y": 9,
      "z": -6,
      "name": "Empty",
      "level": 0
    },
    {
      "x": -1,
      "y": 1,
      "z": -5,
      "name": "Empty",
      "level": 0
    },
    {
      "x": -1,
      "y": 2,
      "z": -5,
      "name": "Empty",
      "level": 0
    },
    {
      "x": -1,
      "y": 3,
      "z": -5,
      "name": "Empty",
      "level": 0
    },
    {
      "x": -1,
      "y": 4,
      "z": -5,
      "name": "Empty",
      "level": 0
    },
    {
      "x": -1,
      "y": 5,
      "z": -5,
      "name": "Empty",
      "level": 0
    },
    {
      "x": -1,
      "y": 6,
      "z": -5,
      "name": "Empty",
      "level": 0
    },
    {
      "x": -1,
      "y": 7,
      "z": -5,
      "name": "Empty",
      "level": 0
    },
    {
      "x": -1,
      "y": 8,
      "z": -5,
      "name": "Empty",
      "level": 0
    },
    {
      "x": -1,
      "y": 9,
      "z": -5,
      "name": "Empty",
      "level": 0
    },
    {
      "x": -1,
      "y": 1,
      "z": -4,
      "name": "Empty",
      "level": 0
    },
    {
      "x": -1,
      "y": 2,
      "z": -4,
      "name": "Empty",
      "level": 0
    },
    {
      "x": -1,
      "y": 3,
      "z": -4,
      "name": "Empty",
      "level": 0
    },
    {
      "x": -1,
      "y": 4,
      "z": -4,
      "name": "Empty",
      "level": 0
    },
    {
      "x": -1,
      "y": 5,
      "z": -4,
      "name": "Empty",
      "level": 0
    },
    {
      "x": -1,
      "y": 6,
      "z": -4,
      "name": "Empty",
      "level": 0
    },
    {
      "x": -1,
      "y": 7,
      "z": -4,
      "name": "Empty",
      "level": 0
    },
    {
      "x": -1,
      "y": 8,
      "z": -4,
      "name": "Empty",
      "level": 0
    },
    {
      "x": -1,
      "y": 9,
      "z": -4,
      "name": "Empty",
      "level": 0
    },
    {
      "x": -1,
      "y": 1,
      "z": -3,
      "name": "Empty",
      "level": 0
    },
    {
      "x": -1,
      "y": 2,
      "z": -3,
      "name": "Empty",
      "level": 0
    },
    {
      "x": -1,
      "y": 3,
      "z": -3,
      "name": "Empty",
      "level": 0
    },
    {
      "x": -1,
      "y": 4,
      "z": -3,
      "name": "Empty",
      "level": 0
    },
    {
      "x": -1,
      "y": 5,
      "z": -3,
      "name": "Empty",
      "level": 0
    },
    {
      "x": -1,
      "y": 6,
      "z": -3,
      "name": "Empty",
      "level": 0
    },
    {
      "x": -1,
      "y": 7,
      "z": -3,
      "name": "Empty",
      "level": 0
    },
    {
      "x": -1,
      "y": 8,
      "z": -3,
      "name": "Empty",
      "level": 0
    },
    {
      "x": -1,
      "y": 9,
      "z": -3,
      "name": "Empty",
      "level": 0
    },
    {
      "x": -1,
      "y": 1,
      "z": -2,
      "name": "Empty",
      "level": 0
    },
    {
      "x": -1,
      "y": 2,
      "z": -2,
      "name": "Empty",
      "level": 0
    },
    {
      "x": -1,
      "y": 3,
      "z": -2,
      "name": "Empty",
      "level": 0
    },
    {
      "x": -1,
      "y": 4,
      "z": -2,
      "name": "Empty",
      "level": 0
    },
    {
      "x": -1,
      "y": 5,
      "z": -2,
      "name": "Empty",
      "level": 0
    },
    {
      "x": -1,
      "y": 6,
      "z": -2,
      "name": "Empty",
      "level": 0
    },
    {
      "x": -1,
      "y": 7,
      "z": -2,
      "name": "Empty",
      "level": 0
    },
    {
      "x": -1,
      "y": 8,
      "z": -2,
      "name": "Empty",
      "level": 0
    },
    {
      "x": -1,
      "y": 9,
      "z": -2,
      "name": "Empty",
      "level": 0
    },
    {
      "x": -1,
      "y": 1,
      "z": -1,
      "name": "Empty",
      "level": 0
    },
    {
      "x": -1,
      "y": 2,
      "z": -1,
      "name": "Empty",
      "level": 0
    },
    {
      "x": -1,
      "y": 3,
      "z": -1,
      "name": "Empty",
      "level": 0
    },
    {
      "x": -1,
      "y": 4,
      "z": -1,
      "name": "Empty",
      "level": 0
    },
    {
      "x": -1,
      "y": 5,
      "z": -1,
      "name": "Empty",
      "level": 0
    },
    {
      "x": -1,
      "y": 6,
      "z": -1,
      "name": "Empty",
      "level": 0
    },
    {
      "x": -1,
      "y": 7,
      "z": -1,
      "name": "Empty",
      "level": 0
    },
    {
      "x": -1,
      "y": 8,
      "z": -1,
      "name": "Empty",
      "level": 0
    },
    {
      "x": -1,
      "y": 9,
      "z": -1,
      "name": "Empty",
      "level": 0
    },
    {
      "x": -1,
      "y": 1,
      "z": 0,
      "name": "Empty",
      "level": 0
    },
    {
      "x": -1,
      "y": 2,
      "z": 0,
      "name": "Empty",
      "level": 0
    },
    {
      "x": -1,
      "y": 3,
      "z": 0,
      "name": "Empty",
      "level": 0
    },
    {
      "x": -1,
      "y": 4,
      "z": 0,
      "name": "Empty",
      "level": 0
    },
    {
      "x": -1,
      "y": 5,
      "z": 0,
      "name": "Empty",
      "level": 0
    },
    {
      "x": -1,
      "y": 6,
      "z": 0,
      "name": "Empty",
      "level": 0
    },
    {
      "x": -1,
      "y": 7,
      "z": 0,
      "name": "Empty",
      "level": 0
    },
    {
      "x": -1,
      "y": 8,
      "z": 0,
      "name": "Empty",
      "level": 0
    },
    {
      "x": -1,
      "y": 9,
      "z": 0,
      "name": "Empty",
      "level": 0
    },
    {
      "x": -1,
      "y": 1,
      "z": 1,
      "name": "Empty",
      "level": 0
    },
    {
      "x": -1,
      "y": 2,
      "z": 1,
      "name": "Empty",
      "level": 0
    },
    {
      "x": -1,
      "y": 3,
      "z": 1,
      "name": "Empty",
      "level": 0
    },
    {
      "x": -1,
      "y": 4,
      "z": 1,
      "name": "Empty",
      "level": 0
    },
    {
      "x": -1,
      "y": 5,
      "z": 1,
      "name": "Empty",
      "level": 0
    },
    {
      "x": -1,
      "y": 6,
      "z": 1,
      "name": "Empty",
      "level": 0
    },
    {
      "x": -1,
      "y": 7,
      "z": 1,
      "name": "Empty",
      "level": 0
    },
    {
      "x": -1,
      "y": 8,
      "z": 1,
      "name": "Empty",
      "level": 0
    },
    {
      "x": -1,
      "y": 9,
      "z": 1,
      "name": "Empty",
      "level": 0
    },
    {
      "x": -1,
      "y": 1,
      "z": 2,
      "name": "Empty",
      "level": 0
    },
    {
      "x": -1,
      "y": 2,
      "z": 2,
      "name": "Empty",
      "level": 0
    },
    {
      "x": -1,
      "y": 3,
      "z": 2,
      "name": "Empty",
      "level": 0
    },
    {
      "x": -1,
      "y": 4,
      "z": 2,
      "name": "Empty",
      "level": 0
    },
    {
      "x": -1,
      "y": 5,
      "z": 2,
      "name": "Empty",
      "level": 0
    },
    {
      "x": -1,
      "y": 6,
      "z": 2,
      "name": "Empty",
      "level": 0
    },
    {
      "x": -1,
      "y": 7,
      "z": 2,
      "name": "Empty",
      "level": 0
    },
    {
      "x": -1,
      "y": 8,
      "z": 2,
      "name": "Empty",
      "level": 0
    },
    {
      "x": -1,
      "y": 9,
      "z": 2,
      "name": "Empty",
      "level": 0
    },
    {
      "x": -1,
      "y": 1,
      "z": 3,
      "name": "Empty",
      "level": 0
    },
    {
      "x": -1,
      "y": 2,
      "z": 3,
      "name": "Empty",
      "level": 0
    },
    {
      "x": -1,
      "y": 3,
      "z": 3,
      "name": "Empty",
      "level": 0
    },
    {
      "x": -1,
      "y": 4,
      "z": 3,
      "name": "Empty",
      "level": 0
    },
    {
      "x": -1,
      "y": 5,
      "z": 3,
      "name": "Empty",
      "level": 0
    },
    {
      "x": -1,
      "y": 6,
      "z": 3,
      "name": "Empty",
      "level": 0
    },
    {
      "x": -1,
      "y": 7,
      "z": 3,
      "name": "Empty",
      "level": 0
    },
    {
      "x": -1,
      "y": 8,
      "z": 3,
      "name": "Empty",
      "level": 0
    },
    {
      "x": -1,
      "y": 9,
      "z": 3,
      "name": "Empty",
      "level": 0
    },
    {
      "x": -1,
      "y": 1,
      "z": 4,
      "name": "Empty",
      "level": 0
    },
    {
      "x": -1,
      "y": 2,
      "z": 4,
      "name": "Empty",
      "level": 0
    },
    {
      "x": -1,
      "y": 3,
      "z": 4,
      "name": "Empty",
      "level": 0
    },
    {
      "x": -1,
      "y": 4,
      "z": 4,
      "name": "Empty",
      "level": 0
    },
    {
      "x": -1,
      "y": 5,
      "z": 4,
      "name": "Empty",
      "level": 0
    },
    {
      "x": -1,
      "y": 6,
      "z": 4,
      "name": "Empty",
      "level": 0
    },
    {
      "x": -1,
      "y": 7,
      "z": 4,
      "name": "Empty",
      "level": 0
    },
    {
      "x": -1,
      "y": 8,
      "z": 4,
      "name": "Empty",
      "level": 0
    },
    {
      "x": -1,
      "y": 9,
      "z": 4,
      "name": "Empty",
      "level": 0
    },
    {
      "x": -1,
      "y": 1,
      "z": 5,
      "name": "Empty",
      "level": 0
    },
    {
      "x": -1,
      "y": 2,
      "z": 5,
      "name": "Empty",
      "level": 0
    },
    {
      "x": -1,
      "y": 3,
      "z": 5,
      "name": "Empty",
      "level": 0
    },
    {
      "x": -1,
      "y": 4,
      "z": 5,
      "name": "Empty",
      "level": 0
    },
    {
      "x": -1,
      "y": 5,
      "z": 5,
      "name": "Empty",
      "level": 0
    },
    {
      "x": -1,
      "y": 6,
      "z": 5,
      "name": "Empty",
      "level": 0
    },
    {
      "x": -1,
      "y": 7,
      "z": 5,
      "name": "Empty",
      "level": 0
    },
    {
      "x": -1,
      "y": 8,
      "z": 5,
      "name": "Empty",
      "level": 0
    },
    {
      "x": -1,
      "y": 9,
      "z": 5,
      "name": "Empty",
      "level": 0
    },
    {
      "x": -1,
      "y": 1,
      "z": 6,
      "name": "Empty",
      "level": 0
    },
    {
      "x": -1,
      "y": 2,
      "z": 6,
      "name": "Empty",
      "level": 0
    },
    {
      "x": -1,
      "y": 3,
      "z": 6,
      "name": "Empty",
      "level": 0
    },
    {
      "x": -1,
      "y": 4,
      "z": 6,
      "name": "Empty",
      "level": 0
    },
    {
      "x": -1,
      "y": 5,
      "z": 6,
      "name": "Empty",
      "level": 0
    },
    {
      "x": -1,
      "y": 6,
      "z": 6,
      "name": "Empty",
      "level": 0
    },
    {
      "x": -1,
      "y": 7,
      "z": 6,
      "name": "Empty",
      "level": 0
    },
    {
      "x": -1,
      "y": 8,
      "z": 6,
      "name": "Empty",
      "level": 0
    },
    {
      "x": -1,
      "y": 9,
      "z": 6,
      "name": "Empty",
      "level": 0
    },
    {
      "x": -1,
      "y": 1,
      "z": 7,
      "name": "Empty",
      "level": 0
    },
    {
      "x": -1,
      "y": 2,
      "z": 7,
      "name": "Empty",
      "level": 0
    },
    {
      "x": -1,
      "y": 3,
      "z": 7,
      "name": "Empty",
      "level": 0
    },
    {
      "x": -1,
      "y": 4,
      "z": 7,
      "name": "Empty",
      "level": 0
    },
    {
      "x": -1,
      "y": 5,
      "z": 7,
      "name": "Empty",
      "level": 0
    },
    {
      "x": -1,
      "y": 6,
      "z": 7,
      "name": "Empty",
      "level": 0
    },
    {
      "x": -1,
      "y": 7,
      "z": 7,
      "name": "Empty",
      "level": 0
    },
    {
      "x": -1,
      "y": 8,
      "z": 7,
      "name": "Empty",
      "level": 0
    },
    {
      "x": -1,
      "y": 9,
      "z": 7,
      "name": "Empty",
      "level": 0
    },
    {
      "x": -1,
      "y": 1,
      "z": 8,
      "name": "Empty",
      "level": 0
    },
    {
      "x": -1,
      "y": 2,
      "z": 8,
      "name": "Empty",
      "level": 0
    },
    {
      "x": -1,
      "y": 3,
      "z": 8,
      "name": "Empty",
      "level": 0
    },
    {
      "x": -1,
      "y": 4,
      "z": 8,
      "name": "Empty",
      "level": 0
    },
    {
      "x": -1,
      "y": 5,
      "z": 8,
      "name": "Empty",
      "level": 0
    },
    {
      "x": -1,
      "y": 6,
      "z": 8,
      "name": "Empty",
      "level": 0
    },
    {
      "x": -1,
      "y": 7,
      "z": 8,
      "name": "Empty",
      "level": 0
    },
    {
      "x": -1,
      "y": 8,
      "z": 8,
      "name": "Empty",
      "level": 0
    },
    {
      "x": -1,
      "y": 9,
      "z": 8,
      "name": "Empty",
      "level": 0
    },
    {
      "x": -1,
      "y": 1,
      "z": 9,
      "name": "Empty",
      "level": 0
    },
    {
      "x": -1,
      "y": 2,
      "z": 9,
      "name": "Empty",
      "level": 0
    },
    {
      "x": -1,
      "y": 3,
      "z": 9,
      "name": "Empty",
      "level": 0
    },
    {
      "x": -1,
      "y": 4,
      "z": 9,
      "name": "Empty",
      "level": 0
    },
    {
      "x": -1,
      "y": 5,
      "z": 9,
      "name": "Empty",
      "level": 0
    },
    {
      "x": -1,
      "y": 6,
      "z": 9,
      "name": "Empty",
      "level": 0
    },
    {
      "x": -1,
      "y": 7,
      "z": 9,
      "name": "Empty",
      "level": 0
    },
    {
      "x": -1,
      "y": 8,
      "z": 9,
      "name": "Empty",
      "level": 0
    },
    {
      "x": -1,
      "y": 9,
      "z": 9,
      "name": "Empty",
      "level": 0
    },
    {
      "x": -1,
      "y": 1,
      "z": 10,
      "name": "Empty",
      "level": 0
    },
    {
      "x": -1,
      "y": 2,
      "z": 10,
      "name": "Empty",
      "level": 0
    },
    {
      "x": -1,
      "y": 3,
      "z": 10,
      "name": "Empty",
      "level": 0
    },
    {
      "x": -1,
      "y": 4,
      "z": 10,
      "name": "Empty",
      "level": 0
    },
    {
      "x": -1,
      "y": 5,
      "z": 10,
      "name": "Empty",
      "level": 0
    },
    {
      "x": -1,
      "y": 6,
      "z": 10,
      "name": "Empty",
      "level": 0
    },
    {
      "x": -1,
      "y": 7,
      "z": 10,
      "name": "Empty",
      "level": 0
    },
    {
      "x": -1,
      "y": 8,
      "z": 10,
      "name": "Empty",
      "level": 0
    },
    {
      "x": -1,
      "y": 9,
      "z": 10,
      "name": "Empty",
      "level": 0
    },
    {
      "x": -1,
      "y": 1,
      "z": 11,
      "name": "Empty",
      "level": 0
    },
    {
      "x": -1,
      "y": 2,
      "z": 11,
      "name": "Empty",
      "level": 0
    },
    {
      "x": -1,
      "y": 3,
      "z": 11,
      "name": "Empty",
      "level": 0
    },
    {
      "x": -1,
      "y": 4,
      "z": 11,
      "name": "Empty",
      "level": 0
    },
    {
      "x": -1,
      "y": 5,
      "z": 11,
      "name": "Empty",
      "level": 0
    },
    {
      "x": -1,
      "y": 6,
      "z": 11,
      "name": "Empty",
      "level": 0
    },
    {
      "x": -1,
      "y": 7,
      "z": 11,
      "name": "Empty",
      "level": 0
    },
    {
      "x": -1,
      "y": 8,
      "z": 11,
      "name": "Empty",
      "level": 0
    },
    {
      "x": -1,
      "y": 9,
      "z": 11,
      "name": "Empty",
      "level": 0
    },
    {
      "x": -1,
      "y": 1,
      "z": 12,
      "name": "Empty",
      "level": 0
    },
    {
      "x": -1,
      "y": 2,
      "z": 12,
      "name": "Empty",
      "level": 0
    },
    {
      "x": -1,
      "y": 3,
      "z": 12,
      "name": "Empty",
      "level": 0
    },
    {
      "x": -1,
      "y": 4,
      "z": 12,
      "name": "Empty",
      "level": 0
    },
    {
      "x": -1,
      "y": 5,
      "z": 12,
      "name": "Empty",
      "level": 0
    },
    {
      "x": -1,
      "y": 6,
      "z": 12,
      "name": "Empty",
      "level": 0
    },
    {
      "x": -1,
      "y": 7,
      "z": 12,
      "name": "Empty",
      "level": 0
    },
    {
      "x": -1,
      "y": 8,
      "z": 12,
      "name": "Empty",
      "level": 0
    },
    {
      "x": -1,
      "y": 9,
      "z": 12,
      "name": "Empty",
      "level": 0
    },
    {
      "x": -1,
      "y": 1,
      "z": 13,
      "name": "Empty",
      "level": 0
    },
    {
      "x": -1,
      "y": 2,
      "z": 13,
      "name": "Empty",
      "level": 0
    },
    {
      "x": -1,
      "y": 3,
      "z": 13,
      "name": "Empty",
      "level": 0
    },
    {
      "x": -1,
      "y": 4,
      "z": 13,
      "name": "Empty",
      "level": 0
    },
    {
      "x": -1,
      "y": 5,
      "z": 13,
      "name": "Empty",
      "level": 0
    },
    {
      "x": -1,
      "y": 6,
      "z": 13,
      "name": "Empty",
      "level": 0
    },
    {
      "x": -1,
      "y": 7,
      "z": 13,
      "name": "Empty",
      "level": 0
    },
    {
      "x": -1,
      "y": 8,
      "z": 13,
      "name": "Empty",
      "level": 0
    },
    {
      "x": -1,
      "y": 9,
      "z": 13,
      "name": "Empty",
      "level": 0
    },
    {
      "x": 0,
      "y": 0,
      "z": -14,
      "name": "Empty",
      "level": 0
    },
    {
      "x": 0,
      "y": 1,
      "z": -14,
      "name": "Empty",
      "level": 0
    },
    {
      "x": 0,
      "y": 2,
      "z": -14,
      "name": "Empty",
      "level": 0
    },
    {
      "x": 0,
      "y": 3,
      "z": -14,
      "name": "Empty",
      "level": 0
    },
    {
      "x": 0,
      "y": 4,
      "z": -14,
      "name": "Empty",
      "level": 0
    },
    {
      "x": 0,
      "y": 5,
      "z": -14,
      "name": "Empty",
      "level": 0
    },
    {
      "x": 0,
      "y": 6,
      "z": -14,
      "name": "Empty",
      "level": 0
    },
    {
      "x": 0,
      "y": 7,
      "z": -14,
      "name": "Empty",
      "level": 0
    },
    {
      "x": 0,
      "y": 8,
      "z": -14,
      "name": "Empty",
      "level": 0
    },
    {
      "x": 0,
      "y": 9,
      "z": -14,
      "name": "Empty",
      "level": 0
    },
    {
      "x": 0,
      "y": 10,
      "z": -14,
      "name": "Empty",
      "level": 0
    },
    {
      "x": 0,
      "y": 0,
      "z": -13,
      "name": "Empty",
      "level": 0
    },
    {
      "x": 0,
      "y": 1,
      "z": -13,
      "name": "Empty",
      "level": 0
    },
    {
      "x": 0,
      "y": 9,
      "z": -13,
      "name": "Empty",
      "level": 0
    },
    {
      "x": 0,
      "y": 10,
      "z": -13,
      "name": "Empty",
      "level": 0
    },
    {
      "x": 0,
      "y": 0,
      "z": -12,
      "name": "Empty",
      "level": 0
    },
    {
      "x": 0,
      "y": 10,
      "z": -12,
      "name": "Empty",
      "level": 0
    },
    {
      "x": 0,
      "y": 0,
      "z": -11,
      "name": "Empty",
      "level": 0
    },
    {
      "x": 0,
      "y": 10,
      "z": -11,
      "name": "Empty",
      "level": 0
    },
    {
      "x": 0,
      "y": 0,
      "z": -10,
      "name": "Empty",
      "level": 0
    },
    {
      "x": 0,
      "y": 10,
      "z": -10,
      "name": "Empty",
      "level": 0
    },
    {
      "x": 0,
      "y": 0,
      "z": -9,
      "name": "Empty",
      "level": 0
    },
    {
      "x": 0,
      "y": 10,
      "z": -9,
      "name": "Empty",
      "level": 0
    },
    {
      "x": 0,
      "y": 0,
      "z": -8,
      "name": "Empty",
      "level": 0
    },
    {
      "x": 0,
      "y": 10,
      "z": -8,
      "name": "Empty",
      "level": 0
    },
    {
      "x": 0,
      "y": 0,
      "z": -7,
      "name": "Empty",
      "level": 0
    },
    {
      "x": 0,
      "y": 10,
      "z": -7,
      "name": "Empty",
      "level": 0
    },
    {
      "x": 0,
      "y": 0,
      "z": -6,
      "name": "Empty",
      "level": 0
    },
    {
      "x": 0,
      "y": 10,
      "z": -6,
      "name": "Empty",
      "level": 0
    },
    {
      "x": 0,
      "y": 0,
      "z": -5,
      "name": "Empty",
      "level": 0
    },
    {
      "x": 0,
      "y": 10,
      "z": -5,
      "name": "Empty",
      "level": 0
    },
    {
      "x": 0,
      "y": 0,
      "z": -4,
      "name": "Empty",
      "level": 0
    },
    {
      "x": 0,
      "y": 10,
      "z": -4,
      "name": "Empty",
      "level": 0
    },
    {
      "x": 0,
      "y": 0,
      "z": -3,
      "name": "Empty",
      "level": 0
    },
    {
      "x": 0,
      "y": 10,
      "z": -3,
      "name": "Empty",
      "level": 0
    },
    {
      "x": 0,
      "y": 0,
      "z": -2,
      "name": "Empty",
      "level": 0
    },
    {
      "x": 0,
      "y": 10,
      "z": -2,
      "name": "Empty",
      "level": 0
    },
    {
      "x": 0,
      "y": 0,
      "z": -1,
      "name": "Empty",
      "level": 0
    },
    {
      "x": 0,
      "y": 2,
      "z": -1,
      "name": "Empty",
      "level": 0
    },
    {
      "x": 0,
      "y": 10,
      "z": -1,
      "name": "Empty",
      "level": 0
    },
    {
      "x": 0,
      "y": 0,
      "z": 0,
      "name": "Empty",
      "level": 0
    },
    {
      "x": 0,
      "y": 10,
      "z": 0,
      "name": "Empty",
      "level": 0
    },
    {
      "x": 0,
      "y": 0,
      "z": 1,
      "name": "Empty",
      "level": 0
    },
    {
      "x": 0,
      "y": 10,
      "z": 1,
      "name": "Empty",
      "level": 0
    },
    {
      "x": 0,
      "y": 0,
      "z": 2,
      "name": "Empty",
      "level": 0
    },
    {
      "x": 0,
      "y": 10,
      "z": 2,
      "name": "Empty",
      "level": 0
    },
    {
      "x": 0,
      "y": 0,
      "z": 3,
      "name": "Empty",
      "level": 0
    },
    {
      "x": 0,
      "y": 10,
      "z": 3,
      "name": "Empty",
      "level": 0
    },
    {
      "x": 0,
      "y": 0,
      "z": 4,
      "name": "Empty",
      "level": 0
    },
    {
      "x": 0,
      "y": 10,
      "z": 4,
      "name": "Empty",
      "level": 0
    },
    {
      "x": 0,
      "y": 0,
      "z": 5,
      "name": "Empty",
      "level": 0
    },
    {
      "x": 0,
      "y": 10,
      "z": 5,
      "name": "Empty",
      "level": 0
    },
    {
      "x": 0,
      "y": 0,
      "z": 6,
      "name": "Empty",
      "level": 0
    },
    {
      "x": 0,
      "y": 10,
      "z": 6,
      "name": "Empty",
      "level": 0
    },
    {
      "x": 0,
      "y": 0,
      "z": 7,
      "name": "Empty",
      "level": 0
    },
    {
      "x": 0,
      "y": 10,
      "z": 7,
      "name": "Empty",
      "level": 0
    },
    {
      "x": 0,
      "y": 0,
      "z": 8,
      "name": "Empty",
      "level": 0
    },
    {
      "x": 0,
      "y": 10,
      "z": 8,
      "name": "Empty",
      "level": 0
    },
    {
      "x": 0,
      "y": 0,
      "z": 9,
      "name": "Empty",
      "level": 0
    },
    {
      "x": 0,
      "y": 10,
      "z": 9,
      "name": "Empty",
      "level": 0
    },
    {
      "x": 0,
      "y": 0,
      "z": 10,
      "name": "Empty",
      "level": 0
    },
    {
      "x": 0,
      "y": 10,
      "z": 10,
      "name": "Empty",
      "level": 0
    },
    {
      "x": 0,
      "y": 0,
      "z": 11,
      "name": "Empty",
      "level": 0
    },
    {
      "x": 0,
      "y": 10,
      "z": 11,
      "name": "Empty",
      "level": 0
    },
    {
      "x": 0,
      "y": 0,
      "z": 12,
      "name": "Empty",
      "level": 0
    },
    {
      "x": 0,
      "y": 10,
      "z": 12,
      "name": "Empty",
      "level": 0
    },
    {
      "x": 0,
      "y": 0,
      "z": 13,
      "name": "Empty",
      "level": 0
    },
    {
      "x": 0,
      "y": 1,
      "z": 13,
      "name": "Empty",
      "level": 0
    },
    {
      "x": 0,
      "y": 9,
      "z": 13,
      "name": "Empty",
      "level": 0
    },
    {
      "x": 0,
      "y": 10,
      "z": 13,
      "name": "Empty",
      "level": 0
    },
    {
      "x": 0,
      "y": 0,
      "z": 14,
      "name": "Empty",
      "level": 0
    },
    {
      "x": 0,
      "y": 1,
      "z": 14,
      "name": "Empty",
      "level": 0
    },
    {
      "x": 0,
      "y": 2,
      "z": 14,
      "name": "Empty",
      "level": 0
    },
    {
      "x": 0,
      "y": 3,
      "z": 14,
      "name": "Empty",
      "level": 0
    },
    {
      "x": 0,
      "y": 4,
      "z": 14,
      "name": "Empty",
      "level": 0
    },
    {
      "x": 0,
      "y": 5,
      "z": 14,
      "name": "Empty",
      "level": 0
    },
    {
      "x": 0,
      "y": 6,
      "z": 14,
